Workbook
Name 伸臂長: '附件1 伸臂重心計算'!$E$3:$K$3

Sheet 安定度計算
A1: 安定度計算(積載型使用)
A3: 一、計算數據：
B5: 1. | C5: 起重機重量(車重+起重機) | I5: (Wb) | K5: = | L5: 8420 | N5: (kg)
B6: 2. | C6: 腳架、立拱重量 | I6: (Wf) | K6: = | L6: 1187 | N6: (kg)
B7: 3. | C7: 伸臂重量 | I7: (Wr) | K7: = | L7: =SUM('附件1 伸臂重心計算'!E5:K5,'附件1 伸臂重心計算'!E7:J8) -> 999 | N7: (kg)
B8: 4. | C8: 車重(不含起重機) | I8: (Ws) | K8: = | L8: =L5-L6-L7-L9 -> 6204 | N8: (kg)
B9: 5. | C9: 吊具組重量 | I9: (Wh) | K9: = | L9: 30 | N9: (kg)
B10: 6. | C10: 前輪距 | I10: (B1) | K10: = | L10: 178.5 | N10: (cm)
B11: 7. | C11: 後輪距 | I11: (B2) | K11: = | L11: 166.5 | N11: (cm)
B12: 8. | C12: 軸距 | I12: (H) | K12: = | L12: 487 | N12: (cm)
B13: 9. | C13: 車高 | I13: (h) | K13: = | L13: 340 | N13: (cm)
B14: 10. | C14: 外伸腳距離 | I14: (Lw) | K14: = | L14: 480 | N14: (cm)
B15: 11. | C15: 吊桿最大起伏角度 | I15: (θm) | K15: = | L15: 78 | N15: (度)
B16: 12. | C16: 前輪到旋轉中心距離 | I16: (S) | K16: = | L16: 70 | N16: (cm)
B17: 13. | C17: 1節時伸臂總長度 | I17: (L1') | K17: = | L17: ='附件1 伸臂重心計算'!E3 -> 393 | N17: (cm)--參照明細表
B18: 14. | C18: 1節時伸臂重心與軸心距離 | I18: (d1) | K18: = | L18: ='附件1 伸臂重心計算'!L11 -> 248.45846 | N18: (cm)--詳附件1
B19: 15. | C19: 平均輪距 | I19: (B) | K19: = | L19: (B1+B2) / 2 = | O19: =(L10+L11)/2 -> 172.5 | Q19: (cm)
B21: 16. | C21: 重心到支點距離_正面 | I21: (L1) | K21: = | L21: (Ws+Wf)×B1/2+Wr×( d1× cosθm+B1/2)+Wh×( L1'× cosθm+B1/2)
L22: Wb
K24: = | L24: =((L8+L6)*L10/2+L7*(L18*COS(RADIANS(L15))+L10/2)+L9*(L17*COS(RADIANS(L15))+L10/2))/L5 -> 95.670076 | N24: (cm)
B26: 17. | C26: 重心到支點距離_側面 | I26: (L2) | K26: = | L26: (Ws×H/3)+(Wf×S)+Wr×(d1× cosθm+S)+Wh×( L1'× cosθm+S)
L27: Wb
K29: = | L29: =((L8*L12/3)+L6*L16+L7*(L18*COS(RADIANS(L15))+L16)+L9*(L17*COS(RADIANS(L15))+L16))/L5 -> 144.45286 | N29: (cm)
B31: 18. | C31: 伸臂中心線至翻倒支點水平距離 | I31: (L') | K31: = | L31: B / 2 = | N31: =O19/2 -> 86.25 | P31: (cm)
B32: 19. | C32: 起重機重心至地面垂直距離 | I32: (h') | K32: = | L32: ='附件3 車台重心高度計算'!L20 -> 125.72859 | N32: (cm)--詳附件3
A34: 二、後方安定度
B36: 1. | C36: 依據移動式起重機安全檢查構造標準第17條第一項第一款：
C37: 伸臂中心線之鉛直面與起重機之行駛方向成直角時，位於伸臂所在側支點上之重量，應為起重機重量之百分之十五以上。
C40: Ra：伸臂所在側支點上之重量(直角) (kg) | L40: B1：前輪距 (m)
C41: Wb：起重機重量 (kg) | L41: L1：重心到支點距離_正面 (m)
C43: Ra ≧ 0.15 × Wb
C45: ∵ Ra ＝ L1 × Wb / B1
C47: ∴ L1 × Wb / B1 ≧ 0.15 × Wb
C49: => L1 / B1 ≧ 0.15
C51: => | D51: =L24 -> 95.670076 | F51: / | G51: =L10 -> 178.5 | I51: = | J51: =D51/G51 -> 0.53596681 | L51: =IF(J51>=0.15,"≧ 0.15 …OK!","≦ 0.15 …不符規定!") -> ≧ 0.15 …OK!
B52: 2. | C52: 依據移動式起重機安全檢查構造標準第17條第一項第二款：
C53: 伸臂中心線之鉛直面與起重機之行駛方向一致時，位於伸臂所在側支點上之重量，應大於起重機重量之百分之十五與平均輪距和軸距之比值之乘積。
C56: Rb：伸臂所在側支點上之重量(平行) (kg) | L56: B：平均輪距 (m) | R56: H：軸距 (m)
C57: Wb：起重機重量 (kg) | L57: L2：重心到支點距離_側面 (m)
C59: Rb ≧ 0.15 × Wb × B / H
...

Sheet 附件1 伸臂重心計算
E1: 第1節 | F1: 第2節 | G1: 第3節 | H1: 第4節 | I1: 第5節 | J1: 第6節 | K1: 第7節 | L1: 總和
E2: 1 | F2: 2 | G2: 3 | H2: 4 | I2: 5 | J2: 6 | K2: 7
A3: 伸臂長(cm) | E3: 393 | F3: 633 | G3: 872 | H3: 1105 | I3: 1338 | J3: 1571
A4: 伸臂各節計算長度(cm) | E4: =E3 -> 393 | F4: =IF(F3="","",F3-E3) -> 240 | G4: =IF(G3="","",G3-F3) -> 239 | H4: =IF(H3="","",H3-G3) -> 233 | I4: =IF(I3="","",I3-H3) -> 233 | J4: =IF(J3="","",J3-I3) -> 233 | K4: =IF(K3="","",K3-J3) | L4: {=SUM(IF($E$4:$K$4="",0,1))} -> 6
A5: 伸臂重量(kg) | E5: 278 | F5: 165 | G5: 136 | H5: 112 | I5: 98 | J5: 85 | L5: =SUM(E5:K5) -> 874
E6: 1 | F6: 2 | G6: 3 | H6: 4 | I6: 5 | J6: 6 | L6: 總和
A7: 油壓缸重量(kg) | E7: 57 | F7: 48 | G7: 20 | L7: {=SUM(IF($E$7:$K$7="",0,1))} -> 3
L8: =SUM(E7:J7) -> 125
L9: 重心位置
A10: 伸出比例 | D10: 1 | E10: =IF(OR($D10>$L$4,E$2>$L$4),"",IF(IF(E$2<=$L$7,IF(E$2>$D10,0,1),($D10-$L$7)/($L$4-$L$7))<=0,0,IF(E$2<=$L$7,1,($D10-$L$7)/($L$4-$L$7)))) -> 1 | F10: =IF(OR($D10>$L$4,F$2>$L$4),"",IF(IF(F$2<=$L$7,IF(F$2>$D10,0,1),($D10-$L$7)/($L$4-$L$7))<=0,0,IF(F$2<=$L$7,1,($D10-$L$7)/($L$4-$L$7)))) -> 0 | G10: =IF(OR($D10>$L$4,G$2>$L$4),"",IF(IF(G$2<=$L$7,IF(G$2>$D10,0,1),($D10-$L$7)/($L$4-$L$7))<=0,0,IF(G$2<=$L$7,1,($D10-$L$7)/($L$4-$L$7)))) -> 0 | H10: =IF(OR($D10>$L$4,H$2>$L$4),"",IF(IF(H$2<=$L$7,IF(H$2>$D10,0,1),($D10-$L$7)/($L$4-$L$7))<=0,0,IF(H$2<=$L$7,1,($D10-$L$7)/($L$4-$L$7)))) -> 0 | I10: =IF(OR($D10>$L$4,I$2>$L$4),"",IF(IF(I$2<=$L$7,IF(I$2>$D10,0,1),($D10-$L$7)/($L$4-$L$7))<=0,0,IF(I$2<=$L$7,1,($D10-$L$7)/($L$4-$L$7)))) -> 0 | J10: =IF(OR($D10>$L$4,J$2>$L$4),"",IF(IF(J$2<=$L$7,IF(J$2>$D10,0,1),($D10-$L$7)/($L$4-$L$7))<=0,0,IF(J$2<=$L$7,1,($D10-$L$7)/($L$4-$L$7)))) -> 0 | K10: =IF(OR($D10>$L$4,K$2>$L$4),"",IF(IF(K$2<=$L$7,IF(K$2>$D10,0,1),($D10-$L$7)/($L$4-$L$7))<=0,0,IF(K$2<=$L$7,1,($D10-$L$7)/($L$4-$L$7)))) | L10: {=IF(D10<=SUM(IF($E$4:$K$4="",0,1)),D10&"節重心(d"&D10&")","")} -> 1節重心(d1)
A11: 伸臂重心位置 | D11: 1 | E11: =IF(E10="","",$E$4/2) -> 196.5 | F11: {=IF(F10="","",SUM($E$4:$F$4*E10:F10)-F$4/2)} -> 273 | G11: {=IF(G10="","",SUM($E$4:$G$4*E10:G10)-G$4/2)} -> 273.5 | H11: {=IF(H10="","",SUM($E$4:$H$4*E10:H10)-H$4/2)} -> 276.5 | I11: {=IF(I10="","",SUM($E$4:$I$4*E10:I10)-I$4/2)} -> 276.5 | J11: {=IF(J10="","",SUM($E$4:$J$4*E10:J10)-J$4/2)} -> 276.5 | K11: {=IF(K10="","",SUM($E$4:$K$4*E10:K10)-K$4/2)} | L11: {=IF(D11>SUM(IF($E$4:$K$4="",0,1)),"",(SUM(IF(E11:K11="",0,E11:K11)*IF($E$5:$K$5="",0,$E$5:$K$5))+SUM(IF($E$7:$J$8="",0,$E$7:$J$8)*IF(E12:J12="",0,E12:J12)))/($L$5+$L$8))} -> 248.45846
A12: 油壓缸重心位置 | D12: 1 | E12: {=IF(OR(E$7="",E10=""),"",(SUM(IF($E$4:$E$4="",0,$E$4:$E$4)*E10:E10)-E$4+SUM(IF($E$4:$F$4="",0,$E$4:$F$4)*E10:F10))/2)} -> 196.5 | F12: {=IF(OR(F$7="",F10=""),"",(SUM(IF($E$4:$F$4="",0,$E$4:$F$4)*E10:F10)-F$4+SUM(IF($E$4:$G$4="",0,$E$4:$G$4)*E10:G10))/2)} -> 273 | G12: {=IF(OR(G$7="",G10=""),"",(SUM(IF($E$4:$G$4="",0,$E$4:$G$4)*E10:G10)-G$4+SUM(IF($E$4:$H$4="",0,$E$4:$H$4)*E10:H10))/2)} -> 273.5 | H12: {=IF(OR(H$7="",H10=""),"",(SUM(IF($E$4:$H$4="",0,$E$4:$H$4)*E10:H10)-H$4+SUM(IF($E$4:$I$4="",0,$E$4:$I$4)*E10:I10))/2)} | I12: {=IF(OR(I$7="",I10=""),"",(SUM(IF($E$4:$I$4="",0,$E$4:$I$4)*E10:I10)-I$4+SUM(IF($E$4:$J$4="",0,$E$4:$J$4)*E10:J10))/2)} | J12: {=IF(OR(J$7="",J10=""),"",(SUM(IF($E$4:$J$4="",0,$E$4:$J$4)*E10:J10)-J$4+SUM(IF($E$4:$K$4="",0,$E$4:$K$4)*E10:K10))/2)}
A13: 伸出比例 | D13: 2 | E13: =IF(OR($D13>$L$4,E$2>$L$4),"",IF(IF(E$2<=$L$7,IF(E$2>$D13,0,1),($D13-$L$7)/($L$4-$L$7))<=0,0,IF(E$2<=$L$7,1,($D13-$L$7)/($L$4-$L$7)))) -> 1 | F13: =IF(OR($D13>$L$4,F$2>$L$4),"",IF(IF(F$2<=$L$7,IF(F$2>$D13,0,1),($D13-$L$7)/($L$4-$L$7))<=0,0,IF(F$2<=$L$7,1,($D13-$L$7)/($L$4-$L$7)))) -> 1 | G13: =IF(OR($D13>$L$4,G$2>$L$4),"",IF(IF(G$2<=$L$7,IF(G$2>$D13,0,1),($D13-$L$7)/($L$4-$L$7))<=0,0,IF(G$2<=$L$7,1,($D13-$L$7)/($L$4-$L$7)))) -> 0 | H13: =IF(OR($D13>$L$4,H$2>$L$4),"",IF(IF(H$2<=$L$7,IF(H$2>$D13,0,1),($D13-$L$7)/($L$4-$L$7))<=0,0,IF(H$2<=$L$7,1,($D13-$L$7)/($L$4-$L$7)))) -> 0 | I13: =IF(OR($D13>$L$4,I$2>$L$4),"",IF(IF(I$2<=$L$7,IF(I$2>$D13,0,1),($D13-$L$7)/($L$4-$L$7))<=0,0,IF(I$2<=$L$7,1,($D13-$L$7)/($L$4-$L$7)))) -> 0 | J13: =IF(OR($D13>$L$4,J$2>$L$4),"",IF(IF(J$2<=$L$7,IF(J$2>$D13,0,1),($D13-$L$7)/($L$4-$L$7))<=0,0,IF(J$2<=$L$7,1,($D13-$L$7)/($L$4-$L$7)))) -> 0 | K13: =IF(OR($D13>$L$4,K$2>$L$4),"",IF(IF(K$2<=$L$7,IF(K$2>$D13,0,1),($D13-$L$7)/($L$4-$L$7))<=0,0,IF(K$2<=$L$7,1,($D13-$L$7)/($L$4-$L$7)))) | L13: {=IF(D13<=SUM(IF($E$4:$K$4="",0,1)),D13&"節重心(d"&D13&")","")} -> 2節重心(d2)
A14: 伸臂重心位置 | D14: 2 | E14: =IF(E13="","",$E$4/2) -> 196.5 | F14: {=IF(F13="","",SUM($E$4:$F$4*E13:F13)-F$4/2)} -> 513 | G14: {=IF(G13="","",SUM($E$4:$G$4*E13:G13)-G$4/2)} -> 513.5 | H14: {=IF(H13="","",SUM($E$4:$H$4*E13:H13)-H$4/2)} -> 516.5 | I14: {=IF(I13="","",SUM($E$4:$I$4*E13:I13)-I$4/2)} -> 516.5 | J14: {=IF(J13="","",SUM($E$4:$J$4*E13:J13)-J$4/2)} -> 516.5 | K14: {=IF(K13="","",SUM($E$4:$K$4*E13:K13)-K$4/2)} | L14: {=IF(D14>SUM(IF($E$4:$K$4="",0,1)),"",(SUM(IF(E14:K14="",0,E14:K14)*IF($E$5:$K$5="",0,$E$5:$K$5))+SUM(IF($E$7:$J$8="",0,$E$7:$J$8)*IF(E15:J15="",0,E15:J15)))/($L$5+$L$8))} -> 414.82482
A15: 油壓缸重心位置 | D15: 2 | E15: {=IF(OR(E$7="",E13=""),"",(SUM(IF($E$4:$E$4="",0,$E$4:$E$4)*E13:E13)-E$4+SUM(IF($E$4:$F$4="",0,$E$4:$F$4)*E13:F13))/2)} -> 316.5 | F15: {=IF(OR(F$7="",F13=""),"",(SUM(IF($E$4:$F$4="",0,$E$4:$F$4)*E13:F13)-F$4+SUM(IF($E$4:$G$4="",0,$E$4:$G$4)*E13:G13))/2)} -> 513 | G15: {=IF(OR(G$7="",G13=""),"",(SUM(IF($E$4:$G$4="",0,$E$4:$G$4)*E13:G13)-G$4+SUM(IF($E$4:$H$4="",0,$E$4:$H$4)*E13:H13))/2)} -> 513.5 | H15: {=IF(OR(H$7="",H13=""),"",(SUM(IF($E$4:$H$4="",0,$E$4:$H$4)*E13:H13)-H$4+SUM(IF($E$4:$I$4="",0,$E$4:$I$4)*E13:I13))/2)} | I15: {=IF(OR(I$7="",I13=""),"",(SUM(IF($E$4:$I$4="",0,$E$4:$I$4)*E13:I13)-I$4+SUM(IF($E$4:$J$4="",0,$E$4:$J$4)*E13:J13))/2)} | J15: {=IF(OR(J$7="",J13=""),"",(SUM(IF($E$4:$J$4="",0,$E$4:$J$4)*E13:J13)-J$4+SUM(IF($E$4:$K$4="",0,$E$4:$K$4)*E13:K13))/2)}
A16: 伸出比例 | D16: 3 | E16: =IF(OR($D16>$L$4,E$2>$L$4),"",IF(IF(E$2<=$L$7,IF(E$2>$D16,0,1),($D16-$L$7)/($L$4-$L$7))<=0,0,IF(E$2<=$L$7,1,($D16-$L$7)/($L$4-$L$7)))) -> 1 | F16: =IF(OR($D16>$L$4,F$2>$L$4),"",IF(IF(F$2<=$L$7,IF(F$2>$D16,0,1),($D16-$L$7)/($L$4-$L$7))<=0,0,IF(F$2<=$L$7,1,($D16-$L$7)/($L$4-$L$7)))) -> 1 | G16: =IF(OR($D16>$L$4,G$2>$L$4),"",IF(IF(G$2<=$L$7,IF(G$2>$D16,0,1),($D16-$L$7)/($L$4-$L$7))<=0,0,IF(G$2<=$L$7,1,($D16-$L$7)/($L$4-$L$7)))) -> 1 | H16: =IF(OR($D16>$L$4,H$2>$L$4),"",IF(IF(H$2<=$L$7,IF(H$2>$D16,0,1),($D16-$L$7)/($L$4-$L$7))<=0,0,IF(H$2<=$L$7,1,($D16-$L$7)/($L$4-$L$7)))) -> 0 | I16: =IF(OR($D16>$L$4,I$2>$L$4),"",IF(IF(I$2<=$L$7,IF(I$2>$D16,0,1),($D16-$L$7)/($L$4-$L$7))<=0,0,IF(I$2<=$L$7,1,($D16-$L$7)/($L$4-$L$7)))) -> 0 | J16: =IF(OR($D16>$L$4,J$2>$L$4),"",IF(IF(J$2<=$L$7,IF(J$2>$D16,0,1),($D16-$L$7)/($L$4-$L$7))<=0,0,IF(J$2<=$L$7,1,($D16-$L$7)/($L$4-$L$7)))) -> 0 | K16: =IF(OR($D16>$L$4,K$2>$L$4),"",IF(IF(K$2<=$L$7,IF(K$2>$D16,0,1),($D16-$L$7)/($L$4-$L$7))<=0,0,IF(K$2<=$L$7,1,($D16-$L$7)/($L$4-$L$7)))) | L16: {=IF(D16<=SUM(IF($E$4:$K$4="",0,1)),D16&"節重心(d"&D16&")","")} -> 3節重心(d3)
A17: 伸臂重心位置 | D17: 3 | E17: =IF(E16="","",$E$4/2) -> 196.5 | F17: {=IF(F16="","",SUM($E$4:$F$4*E16:F16)-F$4/2)} -> 513 | G17: {=IF(G16="","",SUM($E$4:$G$4*E16:G16)-G$4/2)} -> 752.5 | H17: {=IF(H16="","",SUM($E$4:$H$4*E16:H16)-H$4/2)} -> 755.5 | I17: {=IF(I16="","",SUM($E$4:$I$4*E16:I16)-I$4/2)} -> 755.5 | J17: {=IF(J16="","",SUM($E$4:$J$4*E16:J16)-J$4/2)} -> 755.5 | K17: {=IF(K16="","",SUM($E$4:$K$4*E16:K16)-K$4/2)} | L17: {=IF(D17>SUM(IF($E$4:$K$4="",0,1)),"",(SUM(IF(E17:K17="",0,E17:K17)*IF($E$5:$K$5="",0,$E$5:$K$5))+SUM(IF($E$7:$J$8="",0,$E$7:$J$8)*IF(E18:J18="",0,E18:J18)))/($L$5+$L$8))} -> 528.46346
A18: 油壓缸重心位置 | D18: 3 | E18: {=IF(OR(E$7="",E16=""),"",(SUM(IF($E$4:$E$4="",0,$E$4:$E$4)*E16:E16)-E$4+SUM(IF($E$4:$F$4="",0,$E$4:$F$4)*E16:F16))/2)} -> 316.5 | F18: {=IF(OR(F$7="",F16=""),"",(SUM(IF($E$4:$F$4="",0,$E$4:$F$4)*E16:F16)-F$4+SUM(IF($E$4:$G$4="",0,$E$4:$G$4)*E16:G16))/2)} -> 632.5 | G18: {=IF(OR(G$7="",G16=""),"",(SUM(IF($E$4:$G$4="",0,$E$4:$G$4)*E16:G16)-G$4+SUM(IF($E$4:$H$4="",0,$E$4:$H$4)*E16:H16))/2)} -> 752.5 | H18: {=IF(OR(H$7="",H16=""),"",(SUM(IF($E$4:$H$4="",0,$E$4:$H$4)*E16:H16)-H$4+SUM(IF($E$4:$I$4="",0,$E$4:$I$4)*E16:I16))/2)} | I18: {=IF(OR(I$7="",I16=""),"",(SUM(IF($E$4:$I$4="",0,$E$4:$I$4)*E16:I16)-I$4+SUM(IF($E$4:$J$4="",0,$E$4:$J$4)*E16:J16))/2)} | J18: {=IF(OR(J$7="",J16=""),"",(SUM(IF($E$4:$J$4="",0,$E$4:$J$4)*E16:J16)-J$4+SUM(IF($E$4:$K$4="",0,$E$4:$K$4)*E16:K16))/2)}
A19: 伸出比例 | D19: 4 | E19: =IF(OR($D19>$L$4,E$2>$L$4),"",IF(IF(E$2<=$L$7,IF(E$2>$D19,0,1),($D19-$L$7)/($L$4-$L$7))<=0,0,IF(E$2<=$L$7,1,($D19-$L$7)/($L$4-$L$7)))) -> 1 | F19: =IF(OR($D19>$L$4,F$2>$L$4),"",IF(IF(F$2<=$L$7,IF(F$2>$D19,0,1),($D19-$L$7)/($L$4-$L$7))<=0,0,IF(F$2<=$L$7,1,($D19-$L$7)/($L$4-$L$7)))) -> 1 | G19: =IF(OR($D19>$L$4,G$2>$L$4),"",IF(IF(G$2<=$L$7,IF(G$2>$D19,0,1),($D19-$L$7)/($L$4-$L$7))<=0,0,IF(G$2<=$L$7,1,($D19-$L$7)/($L$4-$L$7)))) -> 1 | H19: =IF(OR($D19>$L$4,H$2>$L$4),"",IF(IF(H$2<=$L$7,IF(H$2>$D19,0,1),($D19-$L$7)/($L$4-$L$7))<=0,0,IF(H$2<=$L$7,1,($D19-$L$7)/($L$4-$L$7)))) -> 0.33333333 | I19: =IF(OR($D19>$L$4,I$2>$L$4),"",IF(IF(I$2<=$L$7,IF(I$2>$D19,0,1),($D19-$L$7)/($L$4-$L$7))<=0,0,IF(I$2<=$L$7,1,($D19-$L$7)/($L$4-$L$7)))) -> 0.33333333 | J19: =IF(OR($D19>$L$4,J$2>$L$4),"",IF(IF(J$2<=$L$7,IF(J$2>$D19,0,1),($D19-$L$7)/($L$4-$L$7))<=0,0,IF(J$2<=$L$7,1,($D19-$L$7)/($L$4-$L$7)))) -> 0.33333333 | K19: =IF(OR($D19>$L$4,K$2>$L$4),"",IF(IF(K$2<=$L$7,IF(K$2>$D19,0,1),($D19-$L$7)/($L$4-$L$7))<=0,0,IF(K$2<=$L$7,1,($D19-$L$7)/($L$4-$L$7)))) | L19: {=IF(D19<=SUM(IF($E$4:$K$4="",0,1)),D19&"節重心(d"&D19&")","")} -> 4節重心(d4)
A20: 伸臂重心位置 | D20: 4 | E20: =IF(E19="","",$E$4/2) -> 196.5 | F20: {=IF(F19="","",SUM($E$4:$F$4*E19:F19)-F$4/2)} -> 513 | G20: {=IF(G19="","",SUM($E$4:$G$4*E19:G19)-G$4/2)} -> 752.5 | H20: {=IF(H19="","",SUM($E$4:$H$4*E19:H19)-H$4/2)} -> 833.16667 | I20: {=IF(I19="","",SUM($E$4:$I$4*E19:I19)-I$4/2)} -> 910.83333 | J20: {=IF(J19="","",SUM($E$4:$J$4*E19:J19)-J$4/2)} -> 988.5 | K20: {=IF(K19="","",SUM($E$4:$K$4*E19:K19)-K$4/2)} | L20: {=IF(D20>SUM(IF($E$4:$K$4="",0,1)),"",(SUM(IF(E20:K20="",0,E20:K20)*IF($E$5:$K$5="",0,$E$5:$K$5))+SUM(IF($E$7:$J$8="",0,$E$7:$J$8)*IF(E21:J21="",0,E21:J21)))/($L$5+$L$8))} -> 573.01101
A21: 油壓缸重心位置 | D21: 4 | E21: {=IF(OR(E$7="",E19=""),"",(SUM(IF($E$4:$E$4="",0,$E$4:$E$4)*E19:E19)-E$4+SUM(IF($E$4:$F$4="",0,$E$4:$F$4)*E19:F19))/2)} -> 316.5 | F21: {=IF(OR(F$7="",F19=""),"",(SUM(IF($E$4:$F$4="",0,$E$4:$F$4)*E19:F19)-F$4+SUM(IF($E$4:$G$4="",0,$E$4:$G$4)*E19:G19))/2)} -> 632.5 | G21: {=IF(OR(G$7="",G19=""),"",(SUM(IF($E$4:$G$4="",0,$E$4:$G$4)*E19:G19)-G$4+SUM(IF($E$4:$H$4="",0,$E$4:$H$4)*E19:H19))/2)} -> 791.33333 | H21: {=IF(OR(H$7="",H19=""),"",(SUM(IF($E$4:$H$4="",0,$E$4:$H$4)*E19:H19)-H$4+SUM(IF($E$4:$I$4="",0,$E$4:$I$4)*E19:I19))/2)} | I21: {=IF(OR(I$7="",I19=""),"",(SUM(IF($E$4:$I$4="",0,$E$4:$I$4)*E19:I19)-I$4+SUM(IF($E$4:$J$4="",0,$E$4:$J$4)*E19:J19))/2)} | J21: {=IF(OR(J$7="",J19=""),"",(SUM(IF($E$4:$J$4="",0,$E$4:$J$4)*E19:J19)-J$4+SUM(IF($E$4:$K$4="",0,$E$4:$K$4)*E19:K19))/2)}
A22: 伸出比例 | D22: 5 | E22: =IF(OR($D22>$L$4,E$2>$L$4),"",IF(IF(E$2<=$L$7,IF(E$2>$D22,0,1),($D22-$L$7)/($L$4-$L$7))<=0,0,IF(E$2<=$L$7,1,($D22-$L$7)/($L$4-$L$7)))) -> 1 | F22: =IF(OR($D22>$L$4,F$2>$L$4),"",IF(IF(F$2<=$L$7,IF(F$2>$D22,0,1),($D22-$L$7)/($L$4-$L$7))<=0,0,IF(F$2<=$L$7,1,($D22-$L$7)/($L$4-$L$7)))) -> 1 | G22: =IF(OR($D22>$L$4,G$2>$L$4),"",IF(IF(G$2<=$L$7,IF(G$2>$D22,0,1),($D22-$L$7)/($L$4-$L$7))<=0,0,IF(G$2<=$L$7,1,($D22-$L$7)/($L$4-$L$7)))) -> 1 | H22: =IF(OR($D22>$L$4,H$2>$L$4),"",IF(IF(H$2<=$L$7,IF(H$2>$D22,0,1),($D22-$L$7)/($L$4-$L$7))<=0,0,IF(H$2<=$L$7,1,($D22-$L$7)/($L$4-$L$7)))) -> 0.66666667 | I22: =IF(OR($D22>$L$4,I$2>$L$4),"",IF(IF(I$2<=$L$7,IF(I$2>$D22,0,1),($D22-$L$7)/($L$4-$L$7))<=0,0,IF(I$2<=$L$7,1,($D22-$L$7)/($L$4-$L$7)))) -> 0.66666667 | J22: =IF(OR($D22>$L$4,J$2>$L$4),"",IF(IF(J$2<=$L$7,IF(J$2>$D22,0,1),($D22-$L$7)/($L$4-$L$7))<=0,0,IF(J$2<=$L$7,1,($D22-$L$7)/($L$4-$L$7)))) -> 0.66666667 | K22: =IF(OR($D22>$L$4,K$2>$L$4),"",IF(IF(K$2<=$L$7,IF(K$2>$D22,0,1),($D22-$L$7)/($L$4-$L$7))<=0,0,IF(K$2<=$L$7,1,($D22-$L$7)/($L$4-$L$7)))) | L22: {=IF(D22<=SUM(IF($E$4:$K$4="",0,1)),D22&"節重心(d"&D22&")","")} -> 5節重心(d5)
A23: 伸臂重心位置 | D23: 5 | E23: =IF(E22="","",$E$4/2) -> 196.5 | F23: {=IF(F22="","",SUM($E$4:$F$4*E22:F22)-F$4/2)} -> 513 | G23: {=IF(G22="","",SUM($E$4:$G$4*E22:G22)-G$4/2)} -> 752.5 | H23: {=IF(H22="","",SUM($E$4:$H$4*E22:H22)-H$4/2)} -> 910.83333 | I23: {=IF(I22="","",SUM($E$4:$I$4*E22:I22)-I$4/2)} -> 1066.1667 | J23: {=IF(J22="","",SUM($E$4:$J$4*E22:J22)-J$4/2)} -> 1221.5 | K23: {=IF(K22="","",SUM($E$4:$K$4*E22:K22)-K$4/2)} | L23: {=IF(D23>SUM(IF($E$4:$K$4="",0,1)),"",(SUM(IF(E23:K23="",0,E23:K23)*IF($E$5:$K$5="",0,$E$5:$K$5))+SUM(IF($E$7:$J$8="",0,$E$7:$J$8)*IF(E24:J24="",0,E24:J24)))/($L$5+$L$8))} -> 617.55856
A24: 油壓缸重心位置 | D24: 5 | E24: {=IF(OR(E$7="",E22=""),"",(SUM(IF($E$4:$E$4="",0,$E$4:$E$4)*E22:E22)-E$4+SUM(IF($E$4:$F$4="",0,$E$4:$F$4)*E22:F22))/2)} -> 316.5 | F24: {=IF(OR(F$7="",F22=""),"",(SUM(IF($E$4:$F$4="",0,$E$4:$F$4)*E22:F22)-F$4+SUM(IF($E$4:$G$4="",0,$E$4:$G$4)*E22:G22))/2)} -> 632.5 | G24: {=IF(OR(G$7="",G22=""),"",(SUM(IF($E$4:$G$4="",0,$E$4:$G$4)*E22:G22)-G$4+SUM(IF($E$4:$H$4="",0,$E$4:$H$4)*E22:H22))/2)} -> 830.16667 | H24: {=IF(OR(H$7="",H22=""),"",(SUM(IF($E$4:$H$4="",0,$E$4:$H$4)*E22:H22)-H$4+SUM(IF($E$4:$I$4="",0,$E$4:$I$4)*E22:I22))/2)} | I24: {=IF(OR(I$7="",I22=""),"",(SUM(IF($E$4:$I$4="",0,$E$4:$I$4)*E22:I22)-I$4+SUM(IF($E$4:$J$4="",0,$E$4:$J$4)*E22:J22))/2)} | J24: {=IF(OR(J$7="",J22=""),"",(SUM(IF($E$4:$J$4="",0,$E$4:$J$4)*E22:J22)-J$4+SUM(IF($E$4:$K$4="",0,$E$4:$K$4)*E22:K22))/2)}
A25: 伸出比例 | D25: 6 | E25: =IF(OR($D25>$L$4,E$2>$L$4),"",IF(IF(E$2<=$L$7,IF(E$2>$D25,0,1),($D25-$L$7)/($L$4-$L$7))<=0,0,IF(E$2<=$L$7,1,($D25-$L$7)/($L$4-$L$7)))) -> 1 | F25: =IF(OR($D25>$L$4,F$2>$L$4),"",IF(IF(F$2<=$L$7,IF(F$2>$D25,0,1),($D25-$L$7)/($L$4-$L$7))<=0,0,IF(F$2<=$L$7,1,($D25-$L$7)/($L$4-$L$7)))) -> 1 | G25: =IF(OR($D25>$L$4,G$2>$L$4),"",IF(IF(G$2<=$L$7,IF(G$2>$D25,0,1),($D25-$L$7)/($L$4-$L$7))<=0,0,IF(G$2<=$L$7,1,($D25-$L$7)/($L$4-$L$7)))) -> 1 | H25: =IF(OR($D25>$L$4,H$2>$L$4),"",IF(IF(H$2<=$L$7,IF(H$2>$D25,0,1),($D25-$L$7)/($L$4-$L$7))<=0,0,IF(H$2<=$L$7,1,($D25-$L$7)/($L$4-$L$7)))) -> 1 | I25: =IF(OR($D25>$L$4,I$2>$L$4),"",IF(IF(I$2<=$L$7,IF(I$2>$D25,0,1),($D25-$L$7)/($L$4-$L$7))<=0,0,IF(I$2<=$L$7,1,($D25-$L$7)/($L$4-$L$7)))) -> 1 | J25: =IF(OR($D25>$L$4,J$2>$L$4),"",IF(IF(J$2<=$L$7,IF(J$2>$D25,0,1),($D25-$L$7)/($L$4-$L$7))<=0,0,IF(J$2<=$L$7,1,($D25-$L$7)/($L$4-$L$7)))) -> 1 | K25: =IF(OR($D25>$L$4,K$2>$L$4),"",IF(IF(K$2<=$L$7,IF(K$2>$D25,0,1),($D25-$L$7)/($L$4-$L$7))<=0,0,IF(K$2<=$L$7,1,($D25-$L$7)/($L$4-$L$7)))) | L25: {=IF(D25<=SUM(IF($E$4:$K$4="",0,1)),D25&"節重心(d"&D25&")","")} -> 6節重心(d6)
A26: 伸臂重心位置 | D26: 6 | E26: =IF(E25="","",$E$4/2) -> 196.5 | F26: =IF(F25="","",SUM($E$4:$F$4*E25:F25)-F$4/2) -> 120 | G26: {=IF(G25="","",SUM($E$4:$G$4*E25:G25)-G$4/2)} -> 752.5 | H26: {=IF(H25="","",SUM($E$4:$H$4*E25:H25)-H$4/2)} -> 988.5 | I26: {=IF(I25="","",SUM($E$4:$I$4*E25:I25)-I$4/2)} -> 1221.5 | J26: {=IF(J25="","",SUM($E$4:$J$4*E25:J25)-J$4/2)} -> 1454.5 | K26: {=IF(K25="","",SUM($E$4:$K$4*E25:K25)-K$4/2)} | L26: {=IF(D26>SUM(IF($E$4:$K$4="",0,1)),"",(SUM(IF(E26:K26="",0,E26:K26)*IF($E$5:$K$5="",0,$E$5:$K$5))+SUM(IF($E$7:$J$8="",0,$E$7:$J$8)*IF(E27:J27="",0,E27:J27)))/($L$5+$L$8))} -> 597.1962
A27: 油壓缸重心位置 | D27: 6 | E27: {=IF(OR(E$7="",E25=""),"",(SUM(IF($E$4:$E$4="",0,$E$4:$E$4)*E25:E25)-E$4+SUM(IF($E$4:$F$4="",0,$E$4:$F$4)*E25:F25))/2)} -> 316.5 | F27: {=IF(OR(F$7="",F25=""),"",(SUM(IF($E$4:$F$4="",0,$E$4:$F$4)*E25:F25)-F$4+SUM(IF($E$4:$G$4="",0,$E$4:$G$4)*E25:G25))/2)} -> 632.5 | G27: {=IF(OR(G$7="",G25=""),"",(SUM(IF($E$4:$G$4="",0,$E$4:$G$4)*E25:G25)-G$4+SUM(IF($E$4:$H$4="",0,$E$4:$H$4)*E25:H25))/2)} -> 869 | H27: {=IF(OR(H$7="",H25=""),"",(SUM(IF($E$4:$H$4="",0,$E$4:$H$4)*E25:H25)-H$4+SUM(IF($E$4:$I$4="",0,$E$4:$I$4)*E25:I25))/2)} | I27: {=IF(OR(I$7="",I25=""),"",(SUM(IF($E$4:$I$4="",0,$E$4:$I$4)*E25:I25)-I$4+SUM(IF($E$4:$J$4="",0,$E$4:$J$4)*E25:J25))/2)} | J27: {=IF(OR(J$7="",J25=""),"",(SUM(IF($E$4:$J$4="",0,$E$4:$J$4)*E25:J25)-J$4+SUM(IF($E$4:$K$4="",0,$E$4:$K$4)*E25:K25))/2)}
A28: 伸出比例 | D28: 7 | E28: =IF(OR($D28>$L$4,E$2>$L$4),"",IF(IF(E$2<=$L$7,IF(E$2>$D28,0,1),($D28-$L$7)/($L$4-$L$7))<=0,0,IF(E$2<=$L$7,1,($D28-$L$7)/($L$4-$L$7)))) | F28: =IF(OR($D28>$L$4,F$2>$L$4),"",IF(IF(F$2<=$L$7,IF(F$2>$D28,0,1),($D28-$L$7)/($L$4-$L$7))<=0,0,IF(F$2<=$L$7,1,($D28-$L$7)/($L$4-$L$7)))) | G28: =IF(OR($D28>$L$4,G$2>$L$4),"",IF(IF(G$2<=$L$7,IF(G$2>$D28,0,1),($D28-$L$7)/($L$4-$L$7))<=0,0,IF(G$2<=$L$7,1,($D28-$L$7)/($L$4-$L$7)))) | H28: =IF(OR($D28>$L$4,H$2>$L$4),"",IF(IF(H$2<=$L$7,IF(H$2>$D28,0,1),($D28-$L$7)/($L$4-$L$7))<=0,0,IF(H$2<=$L$7,1,($D28-$L$7)/($L$4-$L$7)))) | I28: =IF(OR($D28>$L$4,I$2>$L$4),"",IF(IF(I$2<=$L$7,IF(I$2>$D28,0,1),($D28-$L$7)/($L$4-$L$7))<=0,0,IF(I$2<=$L$7,1,($D28-$L$7)/($L$4-$L$7)))) | J28: =IF(OR($D28>$L$4,J$2>$L$4),"",IF(IF(J$2<=$L$7,IF(J$2>$D28,0,1),($D28-$L$7)/($L$4-$L$7))<=0,0,IF(J$2<=$L$7,1,($D28-$L$7)/($L$4-$L$7)))) | K28: =IF(OR($D28>$L$4,K$2>$L$4),"",IF(IF(K$2<=$L$7,IF(K$2>$D28,0,1),($D28-$L$7)/($L$4-$L$7))<=0,0,IF(K$2<=$L$7,1,($D28-$L$7)/($L$4-$L$7)))) | L28: {=IF(D28<=SUM(IF($E$4:$K$4="",0,1)),D28&"節重心(d"&D28&")","")}
A29: 伸臂重心位置 | D29: 7 | E29: =IF(E28="","",$E$4/2) | F29: {=IF(F28="","",SUM($E$4:$F$4*E28:F28)-F$4/2)} | G29: {=IF(G28="","",SUM($E$4:$G$4*E28:G28)-G$4/2)} | H29: {=IF(H28="","",SUM($E$4:$H$4*E28:H28)-H$4/2)} | I29: {=IF(I28="","",SUM($E$4:$I$4*E28:I28)-I$4/2)} | J29: {=IF(J28="","",SUM($E$4:$J$4*E28:J28)-J$4/2)} | K29: {=IF(K28="","",SUM($E$4:$K$4*E28:K28)-K$4/2)} | L29: {=IF(D29>SUM(IF($E$4:$K$4="",0,1)),"",(SUM(IF(E29:K29="",0,E29:K29)*IF($E$5:$K$5="",0,$E$5:$K$5))+SUM(IF($E$7:$J$8="",0,$E$7:$J$8)*IF(E30:J30="",0,E30:J30)))/($L$5+$L$8))}
A30: 油壓缸重心位置 | D30: 7 | E30: {=IF(OR(E$7="",E28=""),"",(SUM(IF($E$4:$E$4="",0,$E$4:$E$4)*E28:E28)-E$4+SUM(IF($E$4:$F$4="",0,$E$4:$F$4)*E28:F28))/2)} | F30: {=IF(OR(F$7="",F28=""),"",(SUM(IF($E$4:$F$4="",0,$E$4:$F$4)*E28:F28)-F$4+SUM(IF($E$4:$G$4="",0,$E$4:$G$4)*E28:G28))/2)} | G30: {=IF(OR(G$7="",G28=""),"",(SUM(IF($E$4:$G$4="",0,$E$4:$G$4)*E28:G28)-G$4+SUM(IF($E$4:$H$4="",0,$E$4:$H$4)*E28:H28))/2)} | H30: {=IF(OR(H$7="",H28=""),"",(SUM(IF($E$4:$H$4="",0,$E$4:$H$4)*E28:H28)-H$4+SUM(IF($E$4:$I$4="",0,$E$4:$I$4)*E28:I28))/2)} | I30: {=IF(OR(I$7="",I28=""),"",(SUM(IF($E$4:$I$4="",0,$E$4:$I$4)*E28:I28)-I$4+SUM(IF($E$4:$J$4="",0,$E$4:$J$4)*E28:J28))/2)} | J30: {=IF(OR(J$7="",J28=""),"",(SUM(IF($E$4:$J$4="",0,$E$4:$J$4)*E28:J28)-J$4+SUM(IF($E$4:$K$4="",0,$E$4:$K$4)*E28:K28))/2)}
A32: 伸臂重心計算方式：
A34: 1.計算第n節吊桿重心位置=Σ(第n節伸臂長度 × 第n節伸出比例)-第n節伸臂長度/2
A36: 2.計算油壓缸重心位置= | E36: Σ(第n節伸臂長度 × 第n節伸出比例)-第n節伸臂長度 + Σ(第n+1節伸臂長度 × 第n+1節伸出比例)
E37: 2
A39: 3.重心位置= | D39: Σ(第n節伸臂重心位置 × 第n節伸臂重量) + Σ(第n節油壓缸重心位置 × 第n節油壓缸重量)
D40: 伸臂總重+油壓缸總重

Sheet 附件2 伸臂重量中之前端等價質量
E1: 第1節 | F1: 第2節 | G1: 第3節 | H1: 第4節 | I1: 第5節 | J1: 第6節 | K1: 第7節 | L1: 總和
E2: 1 | F2: 2 | G2: 3 | H2: 4 | I2: 5 | J2: 6 | K2: 7
A3: 伸臂重量(kg) | E3: =IF('附件1 伸臂重心計算'!E5="","",'附件1 伸臂重心計算'!E5) -> 278 | F3: =IF('附件1 伸臂重心計算'!F5="","",'附件1 伸臂重心計算'!F5) -> 165 | G3: =IF('附件1 伸臂重心計算'!G5="","",'附件1 伸臂重心計算'!G5) -> 136 | H3: =IF('附件1 伸臂重心計算'!H5="","",'附件1 伸臂重心計算'!H5) -> 112 | I3: =IF('附件1 伸臂重心計算'!I5="","",'附件1 伸臂重心計算'!I5) -> 98 | J3: =IF('附件1 伸臂重心計算'!J5="","",'附件1 伸臂重心計算'!J5) -> 85 | K3: =IF('附件1 伸臂重心計算'!K5="","",'附件1 伸臂重心計算'!K5) | L3: =SUM(E3:K3) -> 874
E4: 1 | F4: 2 | G4: 3 | H4: 4 | I4: 5 | J4: 6 | L4: 總和
A5: 油壓缸重量(kg) | E5: =IF('附件1 伸臂重心計算'!E7:E7="","",'附件1 伸臂重心計算'!E7:E7) -> 57 | F5: =IF('附件1 伸臂重心計算'!F7:F7="","",'附件1 伸臂重心計算'!F7:F7) -> 48 | G5: =IF('附件1 伸臂重心計算'!G7:G7="","",'附件1 伸臂重心計算'!G7:G7) -> 20 | H5: =IF('附件1 伸臂重心計算'!H7:H7="","",'附件1 伸臂重心計算'!H7:H7) | I5: =IF('附件1 伸臂重心計算'!I7:I7="","",'附件1 伸臂重心計算'!I7:I7) | J5: =IF('附件1 伸臂重心計算'!J7:J7="","",'附件1 伸臂重心計算'!J7:J7) | L5: =SUM(E5:J5) -> 125
A6: 伸臂 | E6: 第1節 | F6: 第2節 | G6: 第3節 | H6: 第4節 | I6: 第5節 | J6: 第6節 | K6: 第7節 | L6: 伸臂重量中之前端等價質量
E7: 1 | F7: 2 | G7: 3 | H7: 4 | I7: 5 | J7: 6 | K7: 7
A8: 伸出1節時起點 | E8: {=IF(OR('附件1 伸臂重心計算'!E$3="",'附件1 伸臂重心計算'!$D10>'附件1 伸臂重心計算'!$L$4),"",SUM(IF('附件1 伸臂重心計算'!$E10:E10="",0,'附件1 伸臂重心計算'!$E10:E10)*IF('附件1 伸臂重心計算'!$E$4:E$4="",0,'附件1 伸臂重心計算'!$E$4:E$4))-'附件1 伸臂重心計算'!E$4)} -> 0 | F8: {=IF(OR('附件1 伸臂重心計算'!F$3="",'附件1 伸臂重心計算'!$D10>'附件1 伸臂重心計算'!$L$4),"",SUM(IF('附件1 伸臂重心計算'!$E10:F10="",0,'附件1 伸臂重心計算'!$E10:F10)*IF('附件1 伸臂重心計算'!$E$4:F$4="",0,'附件1 伸臂重心計算'!$E$4:F$4))-'附件1 伸臂重心計算'!F$4)} -> 153 | G8: {=IF(OR('附件1 伸臂重心計算'!G$3="",'附件1 伸臂重心計算'!$D10>'附件1 伸臂重心計算'!$L$4),"",SUM(IF('附件1 伸臂重心計算'!$E10:G10="",0,'附件1 伸臂重心計算'!$E10:G10)*IF('附件1 伸臂重心計算'!$E$4:G$4="",0,'附件1 伸臂重心計算'!$E$4:G$4))-'附件1 伸臂重心計算'!G$4)} -> 154 | H8: {=IF(OR('附件1 伸臂重心計算'!H$3="",'附件1 伸臂重心計算'!$D10>'附件1 伸臂重心計算'!$L$4),"",SUM(IF('附件1 伸臂重心計算'!$E10:H10="",0,'附件1 伸臂重心計算'!$E10:H10)*IF('附件1 伸臂重心計算'!$E$4:H$4="",0,'附件1 伸臂重心計算'!$E$4:H$4))-'附件1 伸臂重心計算'!H$4)} -> 160 | I8: {=IF(OR('附件1 伸臂重心計算'!I$3="",'附件1 伸臂重心計算'!$D10>'附件1 伸臂重心計算'!$L$4),"",SUM(IF('附件1 伸臂重心計算'!$E10:I10="",0,'附件1 伸臂重心計算'!$E10:I10)*IF('附件1 伸臂重心計算'!$E$4:I$4="",0,'附件1 伸臂重心計算'!$E$4:I$4))-'附件1 伸臂重心計算'!I$4)} -> 160 | J8: {=IF(OR('附件1 伸臂重心計算'!J$3="",'附件1 伸臂重心計算'!$D10>'附件1 伸臂重心計算'!$L$4),"",SUM(IF('附件1 伸臂重心計算'!$E10:J10="",0,'附件1 伸臂重心計算'!$E10:J10)*IF('附件1 伸臂重心計算'!$E$4:J$4="",0,'附件1 伸臂重心計算'!$E$4:J$4))-'附件1 伸臂重心計算'!J$4)} -> 160 | K8: {=IF(OR('附件1 伸臂重心計算'!K$3="",'附件1 伸臂重心計算'!$D10>'附件1 伸臂重心計算'!$L$4),"",SUM(IF('附件1 伸臂重心計算'!$E10:K10="",0,'附件1 伸臂重心計算'!$E10:K10)*IF('附件1 伸臂重心計算'!$E$4:K$4="",0,'附件1 伸臂重心計算'!$E$4:K$4))-'附件1 伸臂重心計算'!K$4)} | L8: =IF('附件1 伸臂重心計算'!D10<='附件1 伸臂重心計算'!$L$4,'附件1 伸臂重心計算'!D10&"節時前端等價質量","") -> 1節時前端等價質量
A9: 伸出1節時終點 | E9: {=IF(OR('附件1 伸臂重心計算'!E$3="",'附件1 伸臂重心計算'!$D10>'附件1 伸臂重心計算'!$L$4),"",SUM(IF('附件1 伸臂重心計算'!$E10:E10="",0,'附件1 伸臂重心計算'!$E10:E10)*IF('附件1 伸臂重心計算'!$E$4:E$4="",0,'附件1 伸臂重心計算'!$E$4:E$4)))} -> 393 | F9: {=IF(OR('附件1 伸臂重心計算'!F$3="",'附件1 伸臂重心計算'!$D10>'附件1 伸臂重心計算'!$L$4),"",SUM(IF('附件1 伸臂重心計算'!$E10:F10="",0,'附件1 伸臂重心計算'!$E10:F10)*IF('附件1 伸臂重心計算'!$E$4:F$4="",0,'附件1 伸臂重心計算'!$E$4:F$4)))} -> 393 | G9: {=IF(OR('附件1 伸臂重心計算'!G$3="",'附件1 伸臂重心計算'!$D10>'附件1 伸臂重心計算'!$L$4),"",SUM(IF('附件1 伸臂重心計算'!$E10:G10="",0,'附件1 伸臂重心計算'!$E10:G10)*IF('附件1 伸臂重心計算'!$E$4:G$4="",0,'附件1 伸臂重心計算'!$E$4:G$4)))} -> 393 | H9: {=IF(OR('附件1 伸臂重心計算'!H$3="",'附件1 伸臂重心計算'!$D10>'附件1 伸臂重心計算'!$L$4),"",SUM(IF('附件1 伸臂重心計算'!$E10:H10="",0,'附件1 伸臂重心計算'!$E10:H10)*IF('附件1 伸臂重心計算'!$E$4:H$4="",0,'附件1 伸臂重心計算'!$E$4:H$4)))} -> 393 | I9: {=IF(OR('附件1 伸臂重心計算'!I$3="",'附件1 伸臂重心計算'!$D10>'附件1 伸臂重心計算'!$L$4),"",SUM(IF('附件1 伸臂重心計算'!$E10:I10="",0,'附件1 伸臂重心計算'!$E10:I10)*IF('附件1 伸臂重心計算'!$E$4:I$4="",0,'附件1 伸臂重心計算'!$E$4:I$4)))} -> 393 | J9: {=IF(OR('附件1 伸臂重心計算'!J$3="",'附件1 伸臂重心計算'!$D10>'附件1 伸臂重心計算'!$L$4),"",SUM(IF('附件1 伸臂重心計算'!$E10:J10="",0,'附件1 伸臂重心計算'!$E10:J10)*IF('附件1 伸臂重心計算'!$E$4:J$4="",0,'附件1 伸臂重心計算'!$E$4:J$4)))} -> 393 | K9: {=IF(OR('附件1 伸臂重心計算'!K$3="",'附件1 伸臂重心計算'!$D10>'附件1 伸臂重心計算'!$L$4),"",SUM(IF('附件1 伸臂重心計算'!$E10:K10="",0,'附件1 伸臂重心計算'!$E10:K10)*IF('附件1 伸臂重心計算'!$E$4:K$4="",0,'附件1 伸臂重心計算'!$E$4:K$4)))}
A10: 伸臂超出重心之長度 | E10: =IF(E9="","",IF(E9>='附件1 伸臂重心計算'!$L11,IF(E8>'附件1 伸臂重心計算'!$L11,E9-E8,E9-'附件1 伸臂重心計算'!$L11),0)) -> 144.54154 | F10: =IF(F9="","",IF(F9>='附件1 伸臂重心計算'!$L11,IF(F8>'附件1 伸臂重心計算'!$L11,F9-F8,F9-'附件1 伸臂重心計算'!$L11),0)) -> 144.54154 | G10: =IF(G9="","",IF(G9>='附件1 伸臂重心計算'!$L11,IF(G8>'附件1 伸臂重心計算'!$L11,G9-G8,G9-'附件1 伸臂重心計算'!$L11),0)) -> 144.54154 | H10: =IF(H9="","",IF(H9>='附件1 伸臂重心計算'!$L11,IF(H8>'附件1 伸臂重心計算'!$L11,H9-H8,H9-'附件1 伸臂重心計算'!$L11),0)) -> 144.54154 | I10: =IF(I9="","",IF(I9>='附件1 伸臂重心計算'!$L11,IF(I8>'附件1 伸臂重心計算'!$L11,I9-I8,I9-'附件1 伸臂重心計算'!$L11),0)) -> 144.54154 | J10: =IF(J9="","",IF(J9>='附件1 伸臂重心計算'!$L11,IF(J8>'附件1 伸臂重心計算'!$L11,J9-J8,J9-'附件1 伸臂重心計算'!$L11),0)) -> 144.54154 | K10: =IF(K9="","",IF(K9>='附件1 伸臂重心計算'!$L11,IF(K8>'附件1 伸臂重心計算'!$L11,K9-K8,K9-'附件1 伸臂重心計算'!$L11),0)) | L10: {=SUM(IF(ISERROR(E10:J10/'附件1 伸臂重心計算'!$E$4:$J$4*'附件1 伸臂重心計算'!$E$5:$J$5),0,E10:J10/'附件1 伸臂重心計算'!$E$4:$J$4*'附件1 伸臂重心計算'!$E$5:$J$5))} -> 466.8708
A11: 伸出2節時起點 | E11: {=IF(OR('附件1 伸臂重心計算'!E$3="",'附件1 伸臂重心計算'!$D13>'附件1 伸臂重心計算'!$L$4),"",SUM(IF('附件1 伸臂重心計算'!$E13:E13="",0,'附件1 伸臂重心計算'!$E13:E13)*IF('附件1 伸臂重心計算'!$E$4:E$4="",0,'附件1 伸臂重心計算'!$E$4:E$4))-'附件1 伸臂重心計算'!E$4)} -> 0 | F11: {=IF(OR('附件1 伸臂重心計算'!F$3="",'附件1 伸臂重心計算'!$D13>'附件1 伸臂重心計算'!$L$4),"",SUM(IF('附件1 伸臂重心計算'!$E13:F13="",0,'附件1 伸臂重心計算'!$E13:F13)*IF('附件1 伸臂重心計算'!$E$4:F$4="",0,'附件1 伸臂重心計算'!$E$4:F$4))-'附件1 伸臂重心計算'!F$4)} -> 393 | G11: {=IF(OR('附件1 伸臂重心計算'!G$3="",'附件1 伸臂重心計算'!$D13>'附件1 伸臂重心計算'!$L$4),"",SUM(IF('附件1 伸臂重心計算'!$E13:G13="",0,'附件1 伸臂重心計算'!$E13:G13)*IF('附件1 伸臂重心計算'!$E$4:G$4="",0,'附件1 伸臂重心計算'!$E$4:G$4))-'附件1 伸臂重心計算'!G$4)} -> 394 | H11: {=IF(OR('附件1 伸臂重心計算'!H$3="",'附件1 伸臂重心計算'!$D13>'附件1 伸臂重心計算'!$L$4),"",SUM(IF('附件1 伸臂重心計算'!$E13:H13="",0,'附件1 伸臂重心計算'!$E13:H13)*IF('附件1 伸臂重心計算'!$E$4:H$4="",0,'附件1 伸臂重心計算'!$E$4:H$4))-'附件1 伸臂重心計算'!H$4)} -> 400 | I11: {=IF(OR('附件1 伸臂重心計算'!I$3="",'附件1 伸臂重心計算'!$D13>'附件1 伸臂重心計算'!$L$4),"",SUM(IF('附件1 伸臂重心計算'!$E13:I13="",0,'附件1 伸臂重心計算'!$E13:I13)*IF('附件1 伸臂重心計算'!$E$4:I$4="",0,'附件1 伸臂重心計算'!$E$4:I$4))-'附件1 伸臂重心計算'!I$4)} -> 400 | J11: {=IF(OR('附件1 伸臂重心計算'!J$3="",'附件1 伸臂重心計算'!$D13>'附件1 伸臂重心計算'!$L$4),"",SUM(IF('附件1 伸臂重心計算'!$E13:J13="",0,'附件1 伸臂重心計算'!$E13:J13)*IF('附件1 伸臂重心計算'!$E$4:J$4="",0,'附件1 伸臂重心計算'!$E$4:J$4))-'附件1 伸臂重心計算'!J$4)} -> 400 | K11: {=IF(OR('附件1 伸臂重心計算'!K$3="",'附件1 伸臂重心計算'!$D13>'附件1 伸臂重心計算'!$L$4),"",SUM(IF('附件1 伸臂重心計算'!$E13:K13="",0,'附件1 伸臂重心計算'!$E13:K13)*IF('附件1 伸臂重心計算'!$E$4:K$4="",0,'附件1 伸臂重心計算'!$E$4:K$4))-'附件1 伸臂重心計算'!K$4)} | L11: =IF('附件1 伸臂重心計算'!D13<='附件1 伸臂重心計算'!$L$4,'附件1 伸臂重心計算'!D13&"節時前端等價質量","") -> 2節時前端等價質量
A12: 伸出2節時終點 | E12: {=IF(OR('附件1 伸臂重心計算'!E$3="",'附件1 伸臂重心計算'!$D13>'附件1 伸臂重心計算'!$L$4),"",SUM(IF('附件1 伸臂重心計算'!$E13:E13="",0,'附件1 伸臂重心計算'!$E13:E13)*IF('附件1 伸臂重心計算'!$E$4:E$4="",0,'附件1 伸臂重心計算'!$E$4:E$4)))} -> 393 | F12: {=IF(OR('附件1 伸臂重心計算'!F$3="",'附件1 伸臂重心計算'!$D13>'附件1 伸臂重心計算'!$L$4),"",SUM(IF('附件1 伸臂重心計算'!$E13:F13="",0,'附件1 伸臂重心計算'!$E13:F13)*IF('附件1 伸臂重心計算'!$E$4:F$4="",0,'附件1 伸臂重心計算'!$E$4:F$4)))} -> 633 | G12: {=IF(OR('附件1 伸臂重心計算'!G$3="",'附件1 伸臂重心計算'!$D13>'附件1 伸臂重心計算'!$L$4),"",SUM(IF('附件1 伸臂重心計算'!$E13:G13="",0,'附件1 伸臂重心計算'!$E13:G13)*IF('附件1 伸臂重心計算'!$E$4:G$4="",0,'附件1 伸臂重心計算'!$E$4:G$4)))} -> 633 | H12: {=IF(OR('附件1 伸臂重心計算'!H$3="",'附件1 伸臂重心計算'!$D13>'附件1 伸臂重心計算'!$L$4),"",SUM(IF('附件1 伸臂重心計算'!$E13:H13="",0,'附件1 伸臂重心計算'!$E13:H13)*IF('附件1 伸臂重心計算'!$E$4:H$4="",0,'附件1 伸臂重心計算'!$E$4:H$4)))} -> 633 | I12: {=IF(OR('附件1 伸臂重心計算'!I$3="",'附件1 伸臂重心計算'!$D13>'附件1 伸臂重心計算'!$L$4),"",SUM(IF('附件1 伸臂重心計算'!$E13:I13="",0,'附件1 伸臂重心計算'!$E13:I13)*IF('附件1 伸臂重心計算'!$E$4:I$4="",0,'附件1 伸臂重心計算'!$E$4:I$4)))} -> 633 | J12: {=IF(OR('附件1 伸臂重心計算'!J$3="",'附件1 伸臂重心計算'!$D13>'附件1 伸臂重心計算'!$L$4),"",SUM(IF('附件1 伸臂重心計算'!$E13:J13="",0,'附件1 伸臂重心計算'!$E13:J13)*IF('附件1 伸臂重心計算'!$E$4:J$4="",0,'附件1 伸臂重心計算'!$E$4:J$4)))} -> 633 | K12: {=IF(OR('附件1 伸臂重心計算'!K$3="",'附件1 伸臂重心計算'!$D13>'附件1 伸臂重心計算'!$L$4),"",SUM(IF('附件1 伸臂重心計算'!$E13:K13="",0,'附件1 伸臂重心計算'!$E13:K13)*IF('附件1 伸臂重心計算'!$E$4:K$4="",0,'附件1 伸臂重心計算'!$E$4:K$4)))}
A13: 伸臂超出重心之長度 | E13: =IF(E12="","",IF(E12>='附件1 伸臂重心計算'!$L14,IF(E11>'附件1 伸臂重心計算'!$L14,E12-E11,E12-'附件1 伸臂重心計算'!$L14),0)) -> 0 | F13: =IF(F12="","",IF(F12>='附件1 伸臂重心計算'!$L14,IF(F11>'附件1 伸臂重心計算'!$L14,F12-F11,F12-'附件1 伸臂重心計算'!$L14),0)) -> 218.17518 | G13: =IF(G12="","",IF(G12>='附件1 伸臂重心計算'!$L14,IF(G11>'附件1 伸臂重心計算'!$L14,G12-G11,G12-'附件1 伸臂重心計算'!$L14),0)) -> 218.17518 | H13: =IF(H12="","",IF(H12>='附件1 伸臂重心計算'!$L14,IF(H11>'附件1 伸臂重心計算'!$L14,H12-H11,H12-'附件1 伸臂重心計算'!$L14),0)) -> 218.17518 | I13: =IF(I12="","",IF(I12>='附件1 伸臂重心計算'!$L14,IF(I11>'附件1 伸臂重心計算'!$L14,I12-I11,I12-'附件1 伸臂重心計算'!$L14),0)) -> 218.17518 | J13: =IF(J12="","",IF(J12>='附件1 伸臂重心計算'!$L14,IF(J11>'附件1 伸臂重心計算'!$L14,J12-J11,J12-'附件1 伸臂重心計算'!$L14),0)) -> 218.17518 | K13: =IF(K12="","",IF(K12>='附件1 伸臂重心計算'!$L14,IF(K11>'附件1 伸臂重心計算'!$L14,K12-K11,K12-'附件1 伸臂重心計算'!$L14),0)) | L13: {=SUM(IF(ISERROR(E13:J13/'附件1 伸臂重心計算'!$E$4:$J$4*'附件1 伸臂重心計算'!$E$5:$J$5),0,E13:J13/'附件1 伸臂重心計算'!$E$4:$J$4*'附件1 伸臂重心計算'!$E$5:$J$5))} -> 550.3757
A14: 伸出3節時起點 | E14: {=IF(OR('附件1 伸臂重心計算'!E$3="",'附件1 伸臂重心計算'!$D16>'附件1 伸臂重心計算'!$L$4),"",SUM(IF('附件1 伸臂重心計算'!$E16:E16="",0,'附件1 伸臂重心計算'!$E16:E16)*IF('附件1 伸臂重心計算'!$E$4:E$4="",0,'附件1 伸臂重心計算'!$E$4:E$4))-'附件1 伸臂重心計算'!E$4)} -> 0 | F14: {=IF(OR('附件1 伸臂重心計算'!F$3="",'附件1 伸臂重心計算'!$D16>'附件1 伸臂重心計算'!$L$4),"",SUM(IF('附件1 伸臂重心計算'!$E16:F16="",0,'附件1 伸臂重心計算'!$E16:F16)*IF('附件1 伸臂重心計算'!$E$4:F$4="",0,'附件1 伸臂重心計算'!$E$4:F$4))-'附件1 伸臂重心計算'!F$4)} -> 393 | G14: {=IF(OR('附件1 伸臂重心計算'!G$3="",'附件1 伸臂重心計算'!$D16>'附件1 伸臂重心計算'!$L$4),"",SUM(IF('附件1 伸臂重心計算'!$E16:G16="",0,'附件1 伸臂重心計算'!$E16:G16)*IF('附件1 伸臂重心計算'!$E$4:G$4="",0,'附件1 伸臂重心計算'!$E$4:G$4))-'附件1 伸臂重心計算'!G$4)} -> 633 | H14: {=IF(OR('附件1 伸臂重心計算'!H$3="",'附件1 伸臂重心計算'!$D16>'附件1 伸臂重心計算'!$L$4),"",SUM(IF('附件1 伸臂重心計算'!$E16:H16="",0,'附件1 伸臂重心計算'!$E16:H16)*IF('附件1 伸臂重心計算'!$E$4:H$4="",0,'附件1 伸臂重心計算'!$E$4:H$4))-'附件1 伸臂重心計算'!H$4)} -> 639 | I14: {=IF(OR('附件1 伸臂重心計算'!I$3="",'附件1 伸臂重心計算'!$D16>'附件1 伸臂重心計算'!$L$4),"",SUM(IF('附件1 伸臂重心計算'!$E16:I16="",0,'附件1 伸臂重心計算'!$E16:I16)*IF('附件1 伸臂重心計算'!$E$4:I$4="",0,'附件1 伸臂重心計算'!$E$4:I$4))-'附件1 伸臂重心計算'!I$4)} -> 639 | J14: {=IF(OR('附件1 伸臂重心計算'!J$3="",'附件1 伸臂重心計算'!$D16>'附件1 伸臂重心計算'!$L$4),"",SUM(IF('附件1 伸臂重心計算'!$E16:J16="",0,'附件1 伸臂重心計算'!$E16:J16)*IF('附件1 伸臂重心計算'!$E$4:J$4="",0,'附件1 伸臂重心計算'!$E$4:J$4))-'附件1 伸臂重心計算'!J$4)} -> 639 | K14: {=IF(OR('附件1 伸臂重心計算'!K$3="",'附件1 伸臂重心計算'!$D16>'附件1 伸臂重心計算'!$L$4),"",SUM(IF('附件1 伸臂重心計算'!$E16:K16="",0,'附件1 伸臂重心計算'!$E16:K16)*IF('附件1 伸臂重心計算'!$E$4:K$4="",0,'附件1 伸臂重心計算'!$E$4:K$4))-'附件1 伸臂重心計算'!K$4)} | L14: =IF('附件1 伸臂重心計算'!D16<='附件1 伸臂重心計算'!$L$4,'附件1 伸臂重心計算'!D16&"節時前端等價質量","") -> 3節時前端等價質量
A15: 伸出3節時終點 | E15: {=IF(OR('附件1 伸臂重心計算'!E$3="",'附件1 伸臂重心計算'!$D16>'附件1 伸臂重心計算'!$L$4),"",SUM(IF('附件1 伸臂重心計算'!$E16:E16="",0,'附件1 伸臂重心計算'!$E16:E16)*IF('附件1 伸臂重心計算'!$E$4:E$4="",0,'附件1 伸臂重心計算'!$E$4:E$4)))} -> 393 | F15: {=IF(OR('附件1 伸臂重心計算'!F$3="",'附件1 伸臂重心計算'!$D16>'附件1 伸臂重心計算'!$L$4),"",SUM(IF('附件1 伸臂重心計算'!$E16:F16="",0,'附件1 伸臂重心計算'!$E16:F16)*IF('附件1 伸臂重心計算'!$E$4:F$4="",0,'附件1 伸臂重心計算'!$E$4:F$4)))} -> 633 | G15: {=IF(OR('附件1 伸臂重心計算'!G$3="",'附件1 伸臂重心計算'!$D16>'附件1 伸臂重心計算'!$L$4),"",SUM(IF('附件1 伸臂重心計算'!$E16:G16="",0,'附件1 伸臂重心計算'!$E16:G16)*IF('附件1 伸臂重心計算'!$E$4:G$4="",0,'附件1 伸臂重心計算'!$E$4:G$4)))} -> 872 | H15: {=IF(OR('附件1 伸臂重心計算'!H$3="",'附件1 伸臂重心計算'!$D16>'附件1 伸臂重心計算'!$L$4),"",SUM(IF('附件1 伸臂重心計算'!$E16:H16="",0,'附件1 伸臂重心計算'!$E16:H16)*IF('附件1 伸臂重心計算'!$E$4:H$4="",0,'附件1 伸臂重心計算'!$E$4:H$4)))} -> 872 | I15: {=IF(OR('附件1 伸臂重心計算'!I$3="",'附件1 伸臂重心計算'!$D16>'附件1 伸臂重心計算'!$L$4),"",SUM(IF('附件1 伸臂重心計算'!$E16:I16="",0,'附件1 伸臂重心計算'!$E16:I16)*IF('附件1 伸臂重心計算'!$E$4:I$4="",0,'附件1 伸臂重心計算'!$E$4:I$4)))} -> 872 | J15: {=IF(OR('附件1 伸臂重心計算'!J$3="",'附件1 伸臂重心計算'!$D16>'附件1 伸臂重心計算'!$L$4),"",SUM(IF('附件1 伸臂重心計算'!$E16:J16="",0,'附件1 伸臂重心計算'!$E16:J16)*IF('附件1 伸臂重心計算'!$E$4:J$4="",0,'附件1 伸臂重心計算'!$E$4:J$4)))} -> 872 | K15: {=IF(OR('附件1 伸臂重心計算'!K$3="",'附件1 伸臂重心計算'!$D16>'附件1 伸臂重心計算'!$L$4),"",SUM(IF('附件1 伸臂重心計算'!$E16:K16="",0,'附件1 伸臂重心計算'!$E16:K16)*IF('附件1 伸臂重心計算'!$E$4:K$4="",0,'附件1 伸臂重心計算'!$E$4:K$4)))}
A16: 伸臂超出重心之長度 | E16: =IF(E15="","",IF(E15>='附件1 伸臂重心計算'!$L17,IF(E14>'附件1 伸臂重心計算'!$L17,E15-E14,E15-'附件1 伸臂重心計算'!$L17),0)) -> 0 | F16: =IF(F15="","",IF(F15>='附件1 伸臂重心計算'!$L17,IF(F14>'附件1 伸臂重心計算'!$L17,F15-F14,F15-'附件1 伸臂重心計算'!$L17),0)) -> 104.53654 | G16: =IF(G15="","",IF(G15>='附件1 伸臂重心計算'!$L17,IF(G14>'附件1 伸臂重心計算'!$L17,G15-G14,G15-'附件1 伸臂重心計算'!$L17),0)) -> 239 | H16: =IF(H15="","",IF(H15>='附件1 伸臂重心計算'!$L17,IF(H14>'附件1 伸臂重心計算'!$L17,H15-H14,H15-'附件1 伸臂重心計算'!$L17),0)) -> 233 | I16: =IF(I15="","",IF(I15>='附件1 伸臂重心計算'!$L17,IF(I14>'附件1 伸臂重心計算'!$L17,I15-I14,I15-'附件1 伸臂重心計算'!$L17),0)) -> 233 | J16: =IF(J15="","",IF(J15>='附件1 伸臂重心計算'!$L17,IF(J14>'附件1 伸臂重心計算'!$L17,J15-J14,J15-'附件1 伸臂重心計算'!$L17),0)) -> 233 | K16: =IF(K15="","",IF(K15>='附件1 伸臂重心計算'!$L17,IF(K14>'附件1 伸臂重心計算'!$L17,K15-K14,K15-'附件1 伸臂重心計算'!$L17),0)) | L16: {=SUM(IF(ISERROR(E16:J16/'附件1 伸臂重心計算'!$E$4:$J$4*'附件1 伸臂重心計算'!$E$5:$J$5),0,E16:J16/'附件1 伸臂重心計算'!$E$4:$J$4*'附件1 伸臂重心計算'!$E$5:$J$5))} -> 502.86887
A17: 伸出4節時起點 | E17: {=IF(OR('附件1 伸臂重心計算'!E$3="",'附件1 伸臂重心計算'!$D19>'附件1 伸臂重心計算'!$L$4),"",SUM(IF('附件1 伸臂重心計算'!$E19:E19="",0,'附件1 伸臂重心計算'!$E19:E19)*IF('附件1 伸臂重心計算'!$E$4:E$4="",0,'附件1 伸臂重心計算'!$E$4:E$4))-'附件1 伸臂重心計算'!E$4)} -> 0 | F17: {=IF(OR('附件1 伸臂重心計算'!F$3="",'附件1 伸臂重心計算'!$D19>'附件1 伸臂重心計算'!$L$4),"",SUM(IF('附件1 伸臂重心計算'!$E19:F19="",0,'附件1 伸臂重心計算'!$E19:F19)*IF('附件1 伸臂重心計算'!$E$4:F$4="",0,'附件1 伸臂重心計算'!$E$4:F$4))-'附件1 伸臂重心計算'!F$4)} -> 393 | G17: {=IF(OR('附件1 伸臂重心計算'!G$3="",'附件1 伸臂重心計算'!$D19>'附件1 伸臂重心計算'!$L$4),"",SUM(IF('附件1 伸臂重心計算'!$E19:G19="",0,'附件1 伸臂重心計算'!$E19:G19)*IF('附件1 伸臂重心計算'!$E$4:G$4="",0,'附件1 伸臂重心計算'!$E$4:G$4))-'附件1 伸臂重心計算'!G$4)} -> 633 | H17: {=IF(OR('附件1 伸臂重心計算'!H$3="",'附件1 伸臂重心計算'!$D19>'附件1 伸臂重心計算'!$L$4),"",SUM(IF('附件1 伸臂重心計算'!$E19:H19="",0,'附件1 伸臂重心計算'!$E19:H19)*IF('附件1 伸臂重心計算'!$E$4:H$4="",0,'附件1 伸臂重心計算'!$E$4:H$4))-'附件1 伸臂重心計算'!H$4)} -> 716.66667 | I17: {=IF(OR('附件1 伸臂重心計算'!I$3="",'附件1 伸臂重心計算'!$D19>'附件1 伸臂重心計算'!$L$4),"",SUM(IF('附件1 伸臂重心計算'!$E19:I19="",0,'附件1 伸臂重心計算'!$E19:I19)*IF('附件1 伸臂重心計算'!$E$4:I$4="",0,'附件1 伸臂重心計算'!$E$4:I$4))-'附件1 伸臂重心計算'!I$4)} -> 794.33333 | J17: {=IF(OR('附件1 伸臂重心計算'!J$3="",'附件1 伸臂重心計算'!$D19>'附件1 伸臂重心計算'!$L$4),"",SUM(IF('附件1 伸臂重心計算'!$E19:J19="",0,'附件1 伸臂重心計算'!$E19:J19)*IF('附件1 伸臂重心計算'!$E$4:J$4="",0,'附件1 伸臂重心計算'!$E$4:J$4))-'附件1 伸臂重心計算'!J$4)} -> 872 | K17: {=IF(OR('附件1 伸臂重心計算'!K$3="",'附件1 伸臂重心計算'!$D19>'附件1 伸臂重心計算'!$L$4),"",SUM(IF('附件1 伸臂重心計算'!$E19:K19="",0,'附件1 伸臂重心計算'!$E19:K19)*IF('附件1 伸臂重心計算'!$E$4:K$4="",0,'附件1 伸臂重心計算'!$E$4:K$4))-'附件1 伸臂重心計算'!K$4)} | L17: =IF('附件1 伸臂重心計算'!D19<='附件1 伸臂重心計算'!$L$4,'附件1 伸臂重心計算'!D19&"節時前端等價質量","") -> 4節時前端等價質量
A18: 伸出4節時終點 | E18: {=IF(OR('附件1 伸臂重心計算'!E$3="",'附件1 伸臂重心計算'!$D19>'附件1 伸臂重心計算'!$L$4),"",SUM(IF('附件1 伸臂重心計算'!$E19:E19="",0,'附件1 伸臂重心計算'!$E19:E19)*IF('附件1 伸臂重心計算'!$E$4:E$4="",0,'附件1 伸臂重心計算'!$E$4:E$4)))} -> 393 | F18: {=IF(OR('附件1 伸臂重心計算'!F$3="",'附件1 伸臂重心計算'!$D19>'附件1 伸臂重心計算'!$L$4),"",SUM(IF('附件1 伸臂重心計算'!$E19:F19="",0,'附件1 伸臂重心計算'!$E19:F19)*IF('附件1 伸臂重心計算'!$E$4:F$4="",0,'附件1 伸臂重心計算'!$E$4:F$4)))} -> 633 | G18: {=IF(OR('附件1 伸臂重心計算'!G$3="",'附件1 伸臂重心計算'!$D19>'附件1 伸臂重心計算'!$L$4),"",SUM(IF('附件1 伸臂重心計算'!$E19:G19="",0,'附件1 伸臂重心計算'!$E19:G19)*IF('附件1 伸臂重心計算'!$E$4:G$4="",0,'附件1 伸臂重心計算'!$E$4:G$4)))} -> 872 | H18: {=IF(OR('附件1 伸臂重心計算'!H$3="",'附件1 伸臂重心計算'!$D19>'附件1 伸臂重心計算'!$L$4),"",SUM(IF('附件1 伸臂重心計算'!$E19:H19="",0,'附件1 伸臂重心計算'!$E19:H19)*IF('附件1 伸臂重心計算'!$E$4:H$4="",0,'附件1 伸臂重心計算'!$E$4:H$4)))} -> 949.66667 | I18: {=IF(OR('附件1 伸臂重心計算'!I$3="",'附件1 伸臂重心計算'!$D19>'附件1 伸臂重心計算'!$L$4),"",SUM(IF('附件1 伸臂重心計算'!$E19:I19="",0,'附件1 伸臂重心計算'!$E19:I19)*IF('附件1 伸臂重心計算'!$E$4:I$4="",0,'附件1 伸臂重心計算'!$E$4:I$4)))} -> 1027.3333 | J18: {=IF(OR('附件1 伸臂重心計算'!J$3="",'附件1 伸臂重心計算'!$D19>'附件1 伸臂重心計算'!$L$4),"",SUM(IF('附件1 伸臂重心計算'!$E19:J19="",0,'附件1 伸臂重心計算'!$E19:J19)*IF('附件1 伸臂重心計算'!$E$4:J$4="",0,'附件1 伸臂重心計算'!$E$4:J$4)))} -> 1105 | K18: {=IF(OR('附件1 伸臂重心計算'!K$3="",'附件1 伸臂重心計算'!$D19>'附件1 伸臂重心計算'!$L$4),"",SUM(IF('附件1 伸臂重心計算'!$E19:K19="",0,'附件1 伸臂重心計算'!$E19:K19)*IF('附件1 伸臂重心計算'!$E$4:K$4="",0,'附件1 伸臂重心計算'!$E$4:K$4)))}
A19: 伸臂超出重心之長度 | E19: =IF(E18="","",IF(E18>='附件1 伸臂重心計算'!$L20,IF(E17>'附件1 伸臂重心計算'!$L20,E18-E17,E18-'附件1 伸臂重心計算'!$L20),0)) -> 0 | F19: =IF(F18="","",IF(F18>='附件1 伸臂重心計算'!$L20,IF(F17>'附件1 伸臂重心計算'!$L20,F18-F17,F18-'附件1 伸臂重心計算'!$L20),0)) -> 59.988989 | G19: =IF(G18="","",IF(G18>='附件1 伸臂重心計算'!$L20,IF(G17>'附件1 伸臂重心計算'!$L20,G18-G17,G18-'附件1 伸臂重心計算'!$L20),0)) -> 239 | H19: =IF(H18="","",IF(H18>='附件1 伸臂重心計算'!$L20,IF(H17>'附件1 伸臂重心計算'!$L20,H18-H17,H18-'附件1 伸臂重心計算'!$L20),0)) -> 233 | I19: =IF(I18="","",IF(I18>='附件1 伸臂重心計算'!$L20,IF(I17>'附件1 伸臂重心計算'!$L20,I18-I17,I18-'附件1 伸臂重心計算'!$L20),0)) -> 233 | J19: =IF(J18="","",IF(J18>='附件1 伸臂重心計算'!$L20,IF(J17>'附件1 伸臂重心計算'!$L20,J18-J17,J18-'附件1 伸臂重心計算'!$L20),0)) -> 233 | K19: =IF(K18="","",IF(K18>='附件1 伸臂重心計算'!$L20,IF(K17>'附件1 伸臂重心計算'!$L20,K18-K17,K18-'附件1 伸臂重心計算'!$L20),0)) | L19: {=SUM(IF(ISERROR(E19:J19/'附件1 伸臂重心計算'!$E$4:$J$4*'附件1 伸臂重心計算'!$E$5:$J$5),0,E19:J19/'附件1 伸臂重心計算'!$E$4:$J$4*'附件1 伸臂重心計算'!$E$5:$J$5))} -> 472.24243
A20: 伸出5節時起點 | E20: {=IF(OR('附件1 伸臂重心計算'!E$3="",'附件1 伸臂重心計算'!$D22>'附件1 伸臂重心計算'!$L$4),"",SUM(IF('附件1 伸臂重心計算'!$E22:E22="",0,'附件1 伸臂重心計算'!$E22:E22)*IF('附件1 伸臂重心計算'!$E$4:E$4="",0,'附件1 伸臂重心計算'!$E$4:E$4))-'附件1 伸臂重心計算'!E$4)} -> 0 | F20: {=IF(OR('附件1 伸臂重心計算'!F$3="",'附件1 伸臂重心計算'!$D22>'附件1 伸臂重心計算'!$L$4),"",SUM(IF('附件1 伸臂重心計算'!$E22:F22="",0,'附件1 伸臂重心計算'!$E22:F22)*IF('附件1 伸臂重心計算'!$E$4:F$4="",0,'附件1 伸臂重心計算'!$E$4:F$4))-'附件1 伸臂重心計算'!F$4)} -> 393 | G20: {=IF(OR('附件1 伸臂重心計算'!G$3="",'附件1 伸臂重心計算'!$D22>'附件1 伸臂重心計算'!$L$4),"",SUM(IF('附件1 伸臂重心計算'!$E22:G22="",0,'附件1 伸臂重心計算'!$E22:G22)*IF('附件1 伸臂重心計算'!$E$4:G$4="",0,'附件1 伸臂重心計算'!$E$4:G$4))-'附件1 伸臂重心計算'!G$4)} -> 633 | H20: {=IF(OR('附件1 伸臂重心計算'!H$3="",'附件1 伸臂重心計算'!$D22>'附件1 伸臂重心計算'!$L$4),"",SUM(IF('附件1 伸臂重心計算'!$E22:H22="",0,'附件1 伸臂重心計算'!$E22:H22)*IF('附件1 伸臂重心計算'!$E$4:H$4="",0,'附件1 伸臂重心計算'!$E$4:H$4))-'附件1 伸臂重心計算'!H$4)} -> 794.33333 | I20: {=IF(OR('附件1 伸臂重心計算'!I$3="",'附件1 伸臂重心計算'!$D22>'附件1 伸臂重心計算'!$L$4),"",SUM(IF('附件1 伸臂重心計算'!$E22:I22="",0,'附件1 伸臂重心計算'!$E22:I22)*IF('附件1 伸臂重心計算'!$E$4:I$4="",0,'附件1 伸臂重心計算'!$E$4:I$4))-'附件1 伸臂重心計算'!I$4)} -> 949.66667 | J20: {=IF(OR('附件1 伸臂重心計算'!J$3="",'附件1 伸臂重心計算'!$D22>'附件1 伸臂重心計算'!$L$4),"",SUM(IF('附件1 伸臂重心計算'!$E22:J22="",0,'附件1 伸臂重心計算'!$E22:J22)*IF('附件1 伸臂重心計算'!$E$4:J$4="",0,'附件1 伸臂重心計算'!$E$4:J$4))-'附件1 伸臂重心計算'!J$4)} -> 1105 | K20: {=IF(OR('附件1 伸臂重心計算'!K$3="",'附件1 伸臂重心計算'!$D22>'附件1 伸臂重心計算'!$L$4),"",SUM(IF('附件1 伸臂重心計算'!$E22:K22="",0,'附件1 伸臂重心計算'!$E22:K22)*IF('附件1 伸臂重心計算'!$E$4:K$4="",0,'附件1 伸臂重心計算'!$E$4:K$4))-'附件1 伸臂重心計算'!K$4)} | L20: =IF('附件1 伸臂重心計算'!D22<='附件1 伸臂重心計算'!$L$4,'附件1 伸臂重心計算'!D22&"節時前端等價質量","") -> 5節時前端等價質量
A21: 伸出5節時終點 | E21: {=IF(OR('附件1 伸臂重心計算'!E$3="",'附件1 伸臂重心計算'!$D22>'附件1 伸臂重心計算'!$L$4),"",SUM(IF('附件1 伸臂重心計算'!$E22:E22="",0,'附件1 伸臂重心計算'!$E22:E22)*IF('附件1 伸臂重心計算'!$E$4:E$4="",0,'附件1 伸臂重心計算'!$E$4:E$4)))} -> 393 | F21: {=IF(OR('附件1 伸臂重心計算'!F$3="",'附件1 伸臂重心計算'!$D22>'附件1 伸臂重心計算'!$L$4),"",SUM(IF('附件1 伸臂重心計算'!$E22:F22="",0,'附件1 伸臂重心計算'!$E22:F22)*IF('附件1 伸臂重心計算'!$E$4:F$4="",0,'附件1 伸臂重心計算'!$E$4:F$4)))} -> 633 | G21: {=IF(OR('附件1 伸臂重心計算'!G$3="",'附件1 伸臂重心計算'!$D22>'附件1 伸臂重心計算'!$L$4),"",SUM(IF('附件1 伸臂重心計算'!$E22:G22="",0,'附件1 伸臂重心計算'!$E22:G22)*IF('附件1 伸臂重心計算'!$E$4:G$4="",0,'附件1 伸臂重心計算'!$E$4:G$4)))} -> 872 | H21: {=IF(OR('附件1 伸臂重心計算'!H$3="",'附件1 伸臂重心計算'!$D22>'附件1 伸臂重心計算'!$L$4),"",SUM(IF('附件1 伸臂重心計算'!$E22:H22="",0,'附件1 伸臂重心計算'!$E22:H22)*IF('附件1 伸臂重心計算'!$E$4:H$4="",0,'附件1 伸臂重心計算'!$E$4:H$4)))} -> 1027.3333 | I21: {=IF(OR('附件1 伸臂重心計算'!I$3="",'附件1 伸臂重心計算'!$D22>'附件1 伸臂重心計算'!$L$4),"",SUM(IF('附件1 伸臂重心計算'!$E22:I22="",0,'附件1 伸臂重心計算'!$E22:I22)*IF('附件1 伸臂重心計算'!$E$4:I$4="",0,'附件1 伸臂重心計算'!$E$4:I$4)))} -> 1182.6667 | J21: {=IF(OR('附件1 伸臂重心計算'!J$3="",'附件1 伸臂重心計算'!$D22>'附件1 伸臂重心計算'!$L$4),"",SUM(IF('附件1 伸臂重心計算'!$E22:J22="",0,'附件1 伸臂重心計算'!$E22:J22)*IF('附件1 伸臂重心計算'!$E$4:J$4="",0,'附件1 伸臂重心計算'!$E$4:J$4)))} -> 1338 | K21: {=IF(OR('附件1 伸臂重心計算'!K$3="",'附件1 伸臂重心計算'!$D22>'附件1 伸臂重心計算'!$L$4),"",SUM(IF('附件1 伸臂重心計算'!$E22:K22="",0,'附件1 伸臂重心計算'!$E22:K22)*IF('附件1 伸臂重心計算'!$E$4:K$4="",0,'附件1 伸臂重心計算'!$E$4:K$4)))}
A22: 伸臂超出重心之長度 | E22: =IF(E21="","",IF(E21>='附件1 伸臂重心計算'!$L23,IF(E20>'附件1 伸臂重心計算'!$L23,E21-E20,E21-'附件1 伸臂重心計算'!$L23),0)) -> 0 | F22: =IF(F21="","",IF(F21>='附件1 伸臂重心計算'!$L23,IF(F20>'附件1 伸臂重心計算'!$L23,F21-F20,F21-'附件1 伸臂重心計算'!$L23),0)) -> 15.441441 | G22: =IF(G21="","",IF(G21>='附件1 伸臂重心計算'!$L23,IF(G20>'附件1 伸臂重心計算'!$L23,G21-G20,G21-'附件1 伸臂重心計算'!$L23),0)) -> 239 | H22: =IF(H21="","",IF(H21>='附件1 伸臂重心計算'!$L23,IF(H20>'附件1 伸臂重心計算'!$L23,H21-H20,H21-'附件1 伸臂重心計算'!$L23),0)) -> 233 | I22: =IF(I21="","",IF(I21>='附件1 伸臂重心計算'!$L23,IF(I20>'附件1 伸臂重心計算'!$L23,I21-I20,I21-'附件1 伸臂重心計算'!$L23),0)) -> 233 | J22: =IF(J21="","",IF(J21>='附件1 伸臂重心計算'!$L23,IF(J20>'附件1 伸臂重心計算'!$L23,J21-J20,J21-'附件1 伸臂重心計算'!$L23),0)) -> 233 | K22: =IF(K21="","",IF(K21>='附件1 伸臂重心計算'!$L23,IF(K20>'附件1 伸臂重心計算'!$L23,K21-K20,K21-'附件1 伸臂重心計算'!$L23),0)) | L22: {=SUM(IF(ISERROR(E22:J22/'附件1 伸臂重心計算'!$E$4:$J$4*'附件1 伸臂重心計算'!$E$5:$J$5),0,E22:J22/'附件1 伸臂重心計算'!$E$4:$J$4*'附件1 伸臂重心計算'!$E$5:$J$5))} -> 441.61599
A23: 伸出6節時起點 | E23: {=IF(OR('附件1 伸臂重心計算'!E$3="",'附件1 伸臂重心計算'!$D25>'附件1 伸臂重心計算'!$L$4),"",SUM(IF('附件1 伸臂重心計算'!$E25:E25="",0,'附件1 伸臂重心計算'!$E25:E25)*IF('附件1 伸臂重心計算'!$E$4:E$4="",0,'附件1 伸臂重心計算'!$E$4:E$4))-'附件1 伸臂重心計算'!E$4)} -> 0 | F23: {=IF(OR('附件1 伸臂重心計算'!F$3="",'附件1 伸臂重心計算'!$D25>'附件1 伸臂重心計算'!$L$4),"",SUM(IF('附件1 伸臂重心計算'!$E25:F25="",0,'附件1 伸臂重心計算'!$E25:F25)*IF('附件1 伸臂重心計算'!$E$4:F$4="",0,'附件1 伸臂重心計算'!$E$4:F$4))-'附件1 伸臂重心計算'!F$4)} -> 393 | G23: {=IF(OR('附件1 伸臂重心計算'!G$3="",'附件1 伸臂重心計算'!$D25>'附件1 伸臂重心計算'!$L$4),"",SUM(IF('附件1 伸臂重心計算'!$E25:G25="",0,'附件1 伸臂重心計算'!$E25:G25)*IF('附件1 伸臂重心計算'!$E$4:G$4="",0,'附件1 伸臂重心計算'!$E$4:G$4))-'附件1 伸臂重心計算'!G$4)} -> 633 | H23: {=IF(OR('附件1 伸臂重心計算'!H$3="",'附件1 伸臂重心計算'!$D25>'附件1 伸臂重心計算'!$L$4),"",SUM(IF('附件1 伸臂重心計算'!$E25:H25="",0,'附件1 伸臂重心計算'!$E25:H25)*IF('附件1 伸臂重心計算'!$E$4:H$4="",0,'附件1 伸臂重心計算'!$E$4:H$4))-'附件1 伸臂重心計算'!H$4)} -> 872 | I23: {=IF(OR('附件1 伸臂重心計算'!I$3="",'附件1 伸臂重心計算'!$D25>'附件1 伸臂重心計算'!$L$4),"",SUM(IF('附件1 伸臂重心計算'!$E25:I25="",0,'附件1 伸臂重心計算'!$E25:I25)*IF('附件1 伸臂重心計算'!$E$4:I$4="",0,'附件1 伸臂重心計算'!$E$4:I$4))-'附件1 伸臂重心計算'!I$4)} -> 1105 | J23: {=IF(OR('附件1 伸臂重心計算'!J$3="",'附件1 伸臂重心計算'!$D25>'附件1 伸臂重心計算'!$L$4),"",SUM(IF('附件1 伸臂重心計算'!$E25:J25="",0,'附件1 伸臂重心計算'!$E25:J25)*IF('附件1 伸臂重心計算'!$E$4:J$4="",0,'附件1 伸臂重心計算'!$E$4:J$4))-'附件1 伸臂重心計算'!J$4)} -> 1338 | K23: {=IF(OR('附件1 伸臂重心計算'!K$3="",'附件1 伸臂重心計算'!$D25>'附件1 伸臂重心計算'!$L$4),"",SUM(IF('附件1 伸臂重心計算'!$E25:K25="",0,'附件1 伸臂重心計算'!$E25:K25)*IF('附件1 伸臂重心計算'!$E$4:K$4="",0,'附件1 伸臂重心計算'!$E$4:K$4))-'附件1 伸臂重心計算'!K$4)} | L23: =IF('附件1 伸臂重心計算'!D25<='附件1 伸臂重心計算'!$L$4,'附件1 伸臂重心計算'!D25&"節時前端等價質量","") -> 6節時前端等價質量
A24: 伸出6節時終點 | E24: {=IF(OR('附件1 伸臂重心計算'!E$3="",'附件1 伸臂重心計算'!$D25>'附件1 伸臂重心計算'!$L$4),"",SUM(IF('附件1 伸臂重心計算'!$E25:E25="",0,'附件1 伸臂重心計算'!$E25:E25)*IF('附件1 伸臂重心計算'!$E$4:E$4="",0,'附件1 伸臂重心計算'!$E$4:E$4)))} -> 393 | F24: {=IF(OR('附件1 伸臂重心計算'!F$3="",'附件1 伸臂重心計算'!$D25>'附件1 伸臂重心計算'!$L$4),"",SUM(IF('附件1 伸臂重心計算'!$E25:F25="",0,'附件1 伸臂重心計算'!$E25:F25)*IF('附件1 伸臂重心計算'!$E$4:F$4="",0,'附件1 伸臂重心計算'!$E$4:F$4)))} -> 633 | G24: {=IF(OR('附件1 伸臂重心計算'!G$3="",'附件1 伸臂重心計算'!$D25>'附件1 伸臂重心計算'!$L$4),"",SUM(IF('附件1 伸臂重心計算'!$E25:G25="",0,'附件1 伸臂重心計算'!$E25:G25)*IF('附件1 伸臂重心計算'!$E$4:G$4="",0,'附件1 伸臂重心計算'!$E$4:G$4)))} -> 872 | H24: {=IF(OR('附件1 伸臂重心計算'!H$3="",'附件1 伸臂重心計算'!$D25>'附件1 伸臂重心計算'!$L$4),"",SUM(IF('附件1 伸臂重心計算'!$E25:H25="",0,'附件1 伸臂重心計算'!$E25:H25)*IF('附件1 伸臂重心計算'!$E$4:H$4="",0,'附件1 伸臂重心計算'!$E$4:H$4)))} -> 1105 | I24: {=IF(OR('附件1 伸臂重心計算'!I$3="",'附件1 伸臂重心計算'!$D25>'附件1 伸臂重心計算'!$L$4),"",SUM(IF('附件1 伸臂重心計算'!$E25:I25="",0,'附件1 伸臂重心計算'!$E25:I25)*IF('附件1 伸臂重心計算'!$E$4:I$4="",0,'附件1 伸臂重心計算'!$E$4:I$4)))} -> 1338 | J24: {=IF(OR('附件1 伸臂重心計算'!J$3="",'附件1 伸臂重心計算'!$D25>'附件1 伸臂重心計算'!$L$4),"",SUM(IF('附件1 伸臂重心計算'!$E25:J25="",0,'附件1 伸臂重心計算'!$E25:J25)*IF('附件1 伸臂重心計算'!$E$4:J$4="",0,'附件1 伸臂重心計算'!$E$4:J$4)))} -> 1571 | K24: {=IF(OR('附件1 伸臂重心計算'!K$3="",'附件1 伸臂重心計算'!$D25>'附件1 伸臂重心計算'!$L$4),"",SUM(IF('附件1 伸臂重心計算'!$E25:K25="",0,'附件1 伸臂重心計算'!$E25:K25)*IF('附件1 伸臂重心計算'!$E$4:K$4="",0,'附件1 伸臂重心計算'!$E$4:K$4)))}
A25: 伸臂超出重心之長度 | E25: =IF(E24="","",IF(E24>='附件1 伸臂重心計算'!$L26,IF(E23>'附件1 伸臂重心計算'!$L26,E24-E23,E24-'附件1 伸臂重心計算'!$L26),0)) -> 0 | F25: =IF(F24="","",IF(F24>='附件1 伸臂重心計算'!$L26,IF(F23>'附件1 伸臂重心計算'!$L26,F24-F23,F24-'附件1 伸臂重心計算'!$L26),0)) -> 35.803804 | G25: =IF(G24="","",IF(G24>='附件1 伸臂重心計算'!$L26,IF(G23>'附件1 伸臂重心計算'!$L26,G24-G23,G24-'附件1 伸臂重心計算'!$L26),0)) -> 239 | H25: =IF(H24="","",IF(H24>='附件1 伸臂重心計算'!$L26,IF(H23>'附件1 伸臂重心計算'!$L26,H24-H23,H24-'附件1 伸臂重心計算'!$L26),0)) -> 233 | I25: =IF(I24="","",IF(I24>='附件1 伸臂重心計算'!$L26,IF(I23>'附件1 伸臂重心計算'!$L26,I24-I23,I24-'附件1 伸臂重心計算'!$L26),0)) -> 233 | J25: =IF(J24="","",IF(J24>='附件1 伸臂重心計算'!$L26,IF(J23>'附件1 伸臂重心計算'!$L26,J24-J23,J24-'附件1 伸臂重心計算'!$L26),0)) -> 233 | K25: =IF(K24="","",IF(K24>='附件1 伸臂重心計算'!$L26,IF(K23>'附件1 伸臂重心計算'!$L26,K24-K23,K24-'附件1 伸臂重心計算'!$L26),0)) | L25: {=SUM(IF(ISERROR(E25:J25/'附件1 伸臂重心計算'!$E$4:$J$4*'附件1 伸臂重心計算'!$E$5:$J$5),0,E25:J25/'附件1 伸臂重心計算'!$E$4:$J$4*'附件1 伸臂重心計算'!$E$5:$J$5))} -> 455.61512
A26: 伸出7節時起點 | E26: {=IF(OR('附件1 伸臂重心計算'!E$3="",'附件1 伸臂重心計算'!$D28>'附件1 伸臂重心計算'!$L$4),"",SUM(IF('附件1 伸臂重心計算'!$E28:E28="",0,'附件1 伸臂重心計算'!$E28:E28)*IF('附件1 伸臂重心計算'!$E$4:E$4="",0,'附件1 伸臂重心計算'!$E$4:E$4))-'附件1 伸臂重心計算'!E$4)} | F26: {=IF(OR('附件1 伸臂重心計算'!F$3="",'附件1 伸臂重心計算'!$D28>'附件1 伸臂重心計算'!$L$4),"",SUM(IF('附件1 伸臂重心計算'!$E28:F28="",0,'附件1 伸臂重心計算'!$E28:F28)*IF('附件1 伸臂重心計算'!$E$4:F$4="",0,'附件1 伸臂重心計算'!$E$4:F$4))-'附件1 伸臂重心計算'!F$4)} | G26: {=IF(OR('附件1 伸臂重心計算'!G$3="",'附件1 伸臂重心計算'!$D28>'附件1 伸臂重心計算'!$L$4),"",SUM(IF('附件1 伸臂重心計算'!$E28:G28="",0,'附件1 伸臂重心計算'!$E28:G28)*IF('附件1 伸臂重心計算'!$E$4:G$4="",0,'附件1 伸臂重心計算'!$E$4:G$4))-'附件1 伸臂重心計算'!G$4)} | H26: {=IF(OR('附件1 伸臂重心計算'!H$3="",'附件1 伸臂重心計算'!$D28>'附件1 伸臂重心計算'!$L$4),"",SUM(IF('附件1 伸臂重心計算'!$E28:H28="",0,'附件1 伸臂重心計算'!$E28:H28)*IF('附件1 伸臂重心計算'!$E$4:H$4="",0,'附件1 伸臂重心計算'!$E$4:H$4))-'附件1 伸臂重心計算'!H$4)} | I26: {=IF(OR('附件1 伸臂重心計算'!I$3="",'附件1 伸臂重心計算'!$D28>'附件1 伸臂重心計算'!$L$4),"",SUM(IF('附件1 伸臂重心計算'!$E28:I28="",0,'附件1 伸臂重心計算'!$E28:I28)*IF('附件1 伸臂重心計算'!$E$4:I$4="",0,'附件1 伸臂重心計算'!$E$4:I$4))-'附件1 伸臂重心計算'!I$4)} | J26: {=IF(OR('附件1 伸臂重心計算'!J$3="",'附件1 伸臂重心計算'!$D28>'附件1 伸臂重心計算'!$L$4),"",SUM(IF('附件1 伸臂重心計算'!$E28:J28="",0,'附件1 伸臂重心計算'!$E28:J28)*IF('附件1 伸臂重心計算'!$E$4:J$4="",0,'附件1 伸臂重心計算'!$E$4:J$4))-'附件1 伸臂重心計算'!J$4)} | K26: {=IF(OR('附件1 伸臂重心計算'!K$3="",'附件1 伸臂重心計算'!$D28>'附件1 伸臂重心計算'!$L$4),"",SUM(IF('附件1 伸臂重心計算'!$E28:K28="",0,'附件1 伸臂重心計算'!$E28:K28)*IF('附件1 伸臂重心計算'!$E$4:K$4="",0,'附件1 伸臂重心計算'!$E$4:K$4))-'附件1 伸臂重心計算'!K$4)} | L26: =IF('附件1 伸臂重心計算'!D28<='附件1 伸臂重心計算'!$L$4,'附件1 伸臂重心計算'!D28&"節時前端等價質量","")
A27: 伸出7節時終點 | E27: {=IF(OR('附件1 伸臂重心計算'!E$3="",'附件1 伸臂重心計算'!$D28>'附件1 伸臂重心計算'!$L$4),"",SUM(IF('附件1 伸臂重心計算'!$E28:E28="",0,'附件1 伸臂重心計算'!$E28:E28)*IF('附件1 伸臂重心計算'!$E$4:E$4="",0,'附件1 伸臂重心計算'!$E$4:E$4)))} | F27: {=IF(OR('附件1 伸臂重心計算'!F$3="",'附件1 伸臂重心計算'!$D28>'附件1 伸臂重心計算'!$L$4),"",SUM(IF('附件1 伸臂重心計算'!$E28:F28="",0,'附件1 伸臂重心計算'!$E28:F28)*IF('附件1 伸臂重心計算'!$E$4:F$4="",0,'附件1 伸臂重心計算'!$E$4:F$4)))} | G27: {=IF(OR('附件1 伸臂重心計算'!G$3="",'附件1 伸臂重心計算'!$D28>'附件1 伸臂重心計算'!$L$4),"",SUM(IF('附件1 伸臂重心計算'!$E28:G28="",0,'附件1 伸臂重心計算'!$E28:G28)*IF('附件1 伸臂重心計算'!$E$4:G$4="",0,'附件1 伸臂重心計算'!$E$4:G$4)))} | H27: {=IF(OR('附件1 伸臂重心計算'!H$3="",'附件1 伸臂重心計算'!$D28>'附件1 伸臂重心計算'!$L$4),"",SUM(IF('附件1 伸臂重心計算'!$E28:H28="",0,'附件1 伸臂重心計算'!$E28:H28)*IF('附件1 伸臂重心計算'!$E$4:H$4="",0,'附件1 伸臂重心計算'!$E$4:H$4)))} | I27: {=IF(OR('附件1 伸臂重心計算'!I$3="",'附件1 伸臂重心計算'!$D28>'附件1 伸臂重心計算'!$L$4),"",SUM(IF('附件1 伸臂重心計算'!$E28:I28="",0,'附件1 伸臂重心計算'!$E28:I28)*IF('附件1 伸臂重心計算'!$E$4:I$4="",0,'附件1 伸臂重心計算'!$E$4:I$4)))} | J27: {=IF(OR('附件1 伸臂重心計算'!J$3="",'附件1 伸臂重心計算'!$D28>'附件1 伸臂重心計算'!$L$4),"",SUM(IF('附件1 伸臂重心計算'!$E28:J28="",0,'附件1 伸臂重心計算'!$E28:J28)*IF('附件1 伸臂重心計算'!$E$4:J$4="",0,'附件1 伸臂重心計算'!$E$4:J$4)))} | K27: {=IF(OR('附件1 伸臂重心計算'!K$3="",'附件1 伸臂重心計算'!$D28>'附件1 伸臂重心計算'!$L$4),"",SUM(IF('附件1 伸臂重心計算'!$E28:K28="",0,'附件1 伸臂重心計算'!$E28:K28)*IF('附件1 伸臂重心計算'!$E$4:K$4="",0,'附件1 伸臂重心計算'!$E$4:K$4)))}
A28: 伸臂超出重心之長度 | E28: =IF(E27="","",IF(E27>='附件1 伸臂重心計算'!$L29,IF(E26>'附件1 伸臂重心計算'!$L29,E27-E26,E27-'附件1 伸臂重心計算'!$L29),0)) | F28: =IF(F27="","",IF(F27>='附件1 伸臂重心計算'!$L29,IF(F26>'附件1 伸臂重心計算'!$L29,F27-F26,F27-'附件1 伸臂重心計算'!$L29),0)) | G28: =IF(G27="","",IF(G27>='附件1 伸臂重心計算'!$L29,IF(G26>'附件1 伸臂重心計算'!$L29,G27-G26,G27-'附件1 伸臂重心計算'!$L29),0)) | H28: =IF(H27="","",IF(H27>='附件1 伸臂重心計算'!$L29,IF(H26>'附件1 伸臂重心計算'!$L29,H27-H26,H27-'附件1 伸臂重心計算'!$L29),0)) | I28: =IF(I27="","",IF(I27>='附件1 伸臂重心計算'!$L29,IF(I26>'附件1 伸臂重心計算'!$L29,I27-I26,I27-'附件1 伸臂重心計算'!$L29),0)) | J28: =IF(J27="","",IF(J27>='附件1 伸臂重心計算'!$L29,IF(J26>'附件1 伸臂重心計算'!$L29,J27-J26,J27-'附件1 伸臂重心計算'!$L29),0)) | K28: =IF(K27="","",IF(K27>='附件1 伸臂重心計算'!$L29,IF(K26>'附件1 伸臂重心計算'!$L29,K27-K26,K27-'附件1 伸臂重心計算'!$L29),0)) | L28: {=SUM(IF(ISERROR(E28:J28/'附件1 伸臂重心計算'!$E$4:$J$4*'附件1 伸臂重心計算'!$E$5:$J$5),0,E28:J28/'附件1 伸臂重心計算'!$E$4:$J$4*'附件1 伸臂重心計算'!$E$5:$J$5))} -> 0
A29: 油壓缸 | E29: 1 | F29: 2 | G29: 3 | H29: 4 | I29: 5 | J29: 6 | L29: 油壓缸重量中之前端等價質量
F30: 2 | G30: 3 | H30: 4 | I30: 5 | J30: 6
A31: 伸出1節時起點 | E31: {=IF(OR('附件1 伸臂重心計算'!$D10>'附件1 伸臂重心計算'!$L$4,'附件1 伸臂重心計算'!E$6>'附件1 伸臂重心計算'!$L$7),"",SUM('附件1 伸臂重心計算'!$E4:E$4*'附件1 伸臂重心計算'!$E10:E$10)-'附件1 伸臂重心計算'!E$4)} -> 0 | F31: {=IF(OR('附件1 伸臂重心計算'!$D10>'附件1 伸臂重心計算'!$L$4,'附件1 伸臂重心計算'!F$6>'附件1 伸臂重心計算'!$L$7),"",SUM('附件1 伸臂重心計算'!$E4:F$4*'附件1 伸臂重心計算'!$E10:F$10)-'附件1 伸臂重心計算'!F$4)} -> 153 | G31: {=IF(OR('附件1 伸臂重心計算'!$D10>'附件1 伸臂重心計算'!$L$4,'附件1 伸臂重心計算'!G$6>'附件1 伸臂重心計算'!$L$7),"",SUM('附件1 伸臂重心計算'!$E4:G$4*'附件1 伸臂重心計算'!$E10:G$10)-'附件1 伸臂重心計算'!G$4)} -> 154 | H31: {=IF(OR('附件1 伸臂重心計算'!$D10>'附件1 伸臂重心計算'!$L$4,'附件1 伸臂重心計算'!H$6>'附件1 伸臂重心計算'!$L$7),"",SUM('附件1 伸臂重心計算'!$E4:H$4*'附件1 伸臂重心計算'!$E10:H$10)-'附件1 伸臂重心計算'!H$4)} | I31: {=IF(OR('附件1 伸臂重心計算'!$D10>'附件1 伸臂重心計算'!$L$4,'附件1 伸臂重心計算'!I$6>'附件1 伸臂重心計算'!$L$7),"",SUM('附件1 伸臂重心計算'!$E4:I$4*'附件1 伸臂重心計算'!$E10:I$10)-'附件1 伸臂重心計算'!I$4)} | J31: {=IF(OR('附件1 伸臂重心計算'!$D10>'附件1 伸臂重心計算'!$L$4,'附件1 伸臂重心計算'!J$6>'附件1 伸臂重心計算'!$L$7),"",SUM('附件1 伸臂重心計算'!$E4:J$4*'附件1 伸臂重心計算'!$E10:J$10)-'附件1 伸臂重心計算'!J$4)} | L31: =IF('附件1 伸臂重心計算'!D10<='附件1 伸臂重心計算'!$L$4,'附件1 伸臂重心計算'!D10&"節時前端等價質量","") -> 1節時前端等價質量
A32: 伸出1節時終點 | E32: {=IF(OR('附件1 伸臂重心計算'!$D10>'附件1 伸臂重心計算'!$L$4,'附件1 伸臂重心計算'!E$6>'附件1 伸臂重心計算'!$L$7),"",SUM('附件1 伸臂重心計算'!$E4:F$4*'附件1 伸臂重心計算'!$E10:F$10))} -> 393 | F32: {=IF(OR('附件1 伸臂重心計算'!$D10>'附件1 伸臂重心計算'!$L$4,'附件1 伸臂重心計算'!F$6>'附件1 伸臂重心計算'!$L$7),"",SUM('附件1 伸臂重心計算'!$E4:G$4*'附件1 伸臂重心計算'!$E10:G$10))} -> 393 | G32: {=IF(OR('附件1 伸臂重心計算'!$D10>'附件1 伸臂重心計算'!$L$4,'附件1 伸臂重心計算'!G$6>'附件1 伸臂重心計算'!$L$7),"",SUM('附件1 伸臂重心計算'!$E4:H$4*'附件1 伸臂重心計算'!$E10:H$10))} -> 393 | H32: {=IF(OR('附件1 伸臂重心計算'!$D10>'附件1 伸臂重心計算'!$L$4,'附件1 伸臂重心計算'!H$6>'附件1 伸臂重心計算'!$L$7),"",SUM('附件1 伸臂重心計算'!$E4:I$4*'附件1 伸臂重心計算'!$E10:I$10))} | I32: {=IF(OR('附件1 伸臂重心計算'!$D10>'附件1 伸臂重心計算'!$L$4,'附件1 伸臂重心計算'!I$6>'附件1 伸臂重心計算'!$L$7),"",SUM('附件1 伸臂重心計算'!$E4:J$4*'附件1 伸臂重心計算'!$E10:J$10))} | J32: {=IF(OR('附件1 伸臂重心計算'!$D10>'附件1 伸臂重心計算'!$L$4,'附件1 伸臂重心計算'!J$6>'附件1 伸臂重心計算'!$L$7),"",SUM('附件1 伸臂重心計算'!$E4:K$4*'附件1 伸臂重心計算'!$E10:K$10))}
A33: 超出重心之長度 | E33: =IF(E32="","",IF(E32>='附件1 伸臂重心計算'!$L11,IF(E31>'附件1 伸臂重心計算'!$L11,E32-E31,E32-'附件1 伸臂重心計算'!$L11),0)) -> 144.54154 | F33: =IF(F32="","",IF(F32>='附件1 伸臂重心計算'!$L11,IF(F31>'附件1 伸臂重心計算'!$L11,F32-F31,F32-'附件1 伸臂重心計算'!$L11),0)) -> 144.54154 | G33: =IF(G32="","",IF(G32>='附件1 伸臂重心計算'!$L11,IF(G31>'附件1 伸臂重心計算'!$L11,G32-G31,G32-'附件1 伸臂重心計算'!$L11),0)) -> 144.54154 | H33: =IF(H32="","",IF(H32>='附件1 伸臂重心計算'!$L11,IF(H31>'附件1 伸臂重心計算'!$L11,H32-H31,H32-'附件1 伸臂重心計算'!$L11),0)) | I33: =IF(I32="","",IF(I32>='附件1 伸臂重心計算'!$L11,IF(I31>'附件1 伸臂重心計算'!$L11,I32-I31,I32-'附件1 伸臂重心計算'!$L11),0)) | J33: =IF(J32="","",IF(J32>='附件1 伸臂重心計算'!$L11,IF(J31>'附件1 伸臂重心計算'!$L11,J9-J31,J9-'附件1 伸臂重心計算'!$L11),0)) | L33: {=SUM(IF(ISERROR(E33:J33/(E32:J32-E31:J31)*'附件1 伸臂重心計算'!$E$7:$H$8),0,E33:J33/(E32:J32-E31:J31)*'附件1 伸臂重心計算'!$E$7:$H$8))} -> 61.967875
A34: 伸出2節時起點 | E34: {=IF(OR('附件1 伸臂重心計算'!$D13>'附件1 伸臂重心計算'!$L$4,'附件1 伸臂重心計算'!E$6>'附件1 伸臂重心計算'!$L$7),"",SUM('附件1 伸臂重心計算'!$E4:E$4*'附件1 伸臂重心計算'!$E13:E$13)-'附件1 伸臂重心計算'!E$4)} -> 0 | F34: {=IF(OR('附件1 伸臂重心計算'!$D13>'附件1 伸臂重心計算'!$L$4,'附件1 伸臂重心計算'!F$6>'附件1 伸臂重心計算'!$L$7),"",SUM('附件1 伸臂重心計算'!$E4:F$4*'附件1 伸臂重心計算'!$E13:F$13)-'附件1 伸臂重心計算'!F$4)} -> 393 | G34: {=IF(OR('附件1 伸臂重心計算'!$D13>'附件1 伸臂重心計算'!$L$4,'附件1 伸臂重心計算'!G$6>'附件1 伸臂重心計算'!$L$7),"",SUM('附件1 伸臂重心計算'!$E4:G$4*'附件1 伸臂重心計算'!$E13:G$13)-'附件1 伸臂重心計算'!G$4)} -> 394 | H34: {=IF(OR('附件1 伸臂重心計算'!$D13>'附件1 伸臂重心計算'!$L$4,'附件1 伸臂重心計算'!H$6>'附件1 伸臂重心計算'!$L$7),"",SUM('附件1 伸臂重心計算'!$E4:H$4*'附件1 伸臂重心計算'!$E13:H$13)-'附件1 伸臂重心計算'!H$4)} | I34: {=IF(OR('附件1 伸臂重心計算'!$D13>'附件1 伸臂重心計算'!$L$4,'附件1 伸臂重心計算'!I$6>'附件1 伸臂重心計算'!$L$7),"",SUM('附件1 伸臂重心計算'!$E4:I$4*'附件1 伸臂重心計算'!$E13:I$13)-'附件1 伸臂重心計算'!I$4)} | J34: {=IF(OR('附件1 伸臂重心計算'!$D13>'附件1 伸臂重心計算'!$L$4,'附件1 伸臂重心計算'!J$6>'附件1 伸臂重心計算'!$L$7),"",SUM('附件1 伸臂重心計算'!$E4:J$4*'附件1 伸臂重心計算'!$E13:J$13)-'附件1 伸臂重心計算'!J$4)} | L34: =IF('附件1 伸臂重心計算'!D13<='附件1 伸臂重心計算'!$L$4,'附件1 伸臂重心計算'!D13&"節時前端等價質量","") -> 2節時前端等價質量
A35: 伸出2節時終點 | E35: {=IF(OR('附件1 伸臂重心計算'!$D13>'附件1 伸臂重心計算'!$L$4,'附件1 伸臂重心計算'!E$6>'附件1 伸臂重心計算'!$L$7),"",SUM('附件1 伸臂重心計算'!$E4:F$4*'附件1 伸臂重心計算'!$E13:F$13))} -> 633 | F35: {=IF(OR('附件1 伸臂重心計算'!$D13>'附件1 伸臂重心計算'!$L$4,'附件1 伸臂重心計算'!F$6>'附件1 伸臂重心計算'!$L$7),"",SUM('附件1 伸臂重心計算'!$E4:G$4*'附件1 伸臂重心計算'!$E13:G$13))} -> 633 | G35: {=IF(OR('附件1 伸臂重心計算'!$D13>'附件1 伸臂重心計算'!$L$4,'附件1 伸臂重心計算'!G$6>'附件1 伸臂重心計算'!$L$7),"",SUM('附件1 伸臂重心計算'!$E4:H$4*'附件1 伸臂重心計算'!$E13:H$13))} -> 633 | H35: {=IF(OR('附件1 伸臂重心計算'!$D13>'附件1 伸臂重心計算'!$L$4,'附件1 伸臂重心計算'!H$6>'附件1 伸臂重心計算'!$L$7),"",SUM('附件1 伸臂重心計算'!$E4:I$4*'附件1 伸臂重心計算'!$E13:I$13))} | I35: {=IF(OR('附件1 伸臂重心計算'!$D13>'附件1 伸臂重心計算'!$L$4,'附件1 伸臂重心計算'!I$6>'附件1 伸臂重心計算'!$L$7),"",SUM('附件1 伸臂重心計算'!$E4:J$4*'附件1 伸臂重心計算'!$E13:J$13))} | J35: {=IF(OR('附件1 伸臂重心計算'!$D13>'附件1 伸臂重心計算'!$L$4,'附件1 伸臂重心計算'!J$6>'附件1 伸臂重心計算'!$L$7),"",SUM('附件1 伸臂重心計算'!$E4:K$4*'附件1 伸臂重心計算'!$E13:K$13))}
A36: 超出重心之長度 | E36: =IF(E35="","",IF(E35>='附件1 伸臂重心計算'!$L14,IF(E34>'附件1 伸臂重心計算'!$L14,E35-E34,E35-'附件1 伸臂重心計算'!$L14),0)) -> 218.17518 | F36: =IF(F35="","",IF(F35>='附件1 伸臂重心計算'!$L14,IF(F34>'附件1 伸臂重心計算'!$L14,F35-F34,F35-'附件1 伸臂重心計算'!$L14),0)) -> 218.17518 | G36: =IF(G35="","",IF(G35>='附件1 伸臂重心計算'!$L14,IF(G34>'附件1 伸臂重心計算'!$L14,G35-G34,G35-'附件1 伸臂重心計算'!$L14),0)) -> 218.17518 | H36: =IF(H35="","",IF(H35>='附件1 伸臂重心計算'!$L14,IF(H34>'附件1 伸臂重心計算'!$L14,H35-H34,H35-'附件1 伸臂重心計算'!$L14),0)) | I36: =IF(I35="","",IF(I35>='附件1 伸臂重心計算'!$L14,IF(I34>'附件1 伸臂重心計算'!$L14,I35-I34,I35-'附件1 伸臂重心計算'!$L14),0)) | J36: =IF(J35="","",IF(J35>='附件1 伸臂重心計算'!$L14,IF(J34>'附件1 伸臂重心計算'!$L14,J12-J34,J12-'附件1 伸臂重心計算'!$L14),0)) | L36: {=SUM(IF(ISERROR(E36:J36/(E35:J35-E34:J34)*'附件1 伸臂重心計算'!$E$7:$H$8),0,E36:J36/(E35:J35-E34:J34)*'附件1 伸臂重心計算'!$E$7:$H$8))} -> 81.538478
A37: 伸出3節時起點 | E37: {=IF(OR('附件1 伸臂重心計算'!$D16>'附件1 伸臂重心計算'!$L$4,'附件1 伸臂重心計算'!E$6>'附件1 伸臂重心計算'!$L$7),"",SUM('附件1 伸臂重心計算'!$E4:E$4*'附件1 伸臂重心計算'!$E16:E$16)-'附件1 伸臂重心計算'!E$4)} -> 0 | F37: {=IF(OR('附件1 伸臂重心計算'!$D16>'附件1 伸臂重心計算'!$L$4,'附件1 伸臂重心計算'!F$6>'附件1 伸臂重心計算'!$L$7),"",SUM('附件1 伸臂重心計算'!$E4:F$4*'附件1 伸臂重心計算'!$E16:F$16)-'附件1 伸臂重心計算'!F$4)} -> 393 | G37: {=IF(OR('附件1 伸臂重心計算'!$D16>'附件1 伸臂重心計算'!$L$4,'附件1 伸臂重心計算'!G$6>'附件1 伸臂重心計算'!$L$7),"",SUM('附件1 伸臂重心計算'!$E4:G$4*'附件1 伸臂重心計算'!$E16:G$16)-'附件1 伸臂重心計算'!G$4)} -> 633 | H37: {=IF(OR('附件1 伸臂重心計算'!$D16>'附件1 伸臂重心計算'!$L$4,'附件1 伸臂重心計算'!H$6>'附件1 伸臂重心計算'!$L$7),"",SUM('附件1 伸臂重心計算'!$E4:H$4*'附件1 伸臂重心計算'!$E16:H$16)-'附件1 伸臂重心計算'!H$4)} | I37: {=IF(OR('附件1 伸臂重心計算'!$D16>'附件1 伸臂重心計算'!$L$4,'附件1 伸臂重心計算'!I$6>'附件1 伸臂重心計算'!$L$7),"",SUM('附件1 伸臂重心計算'!$E4:I$4*'附件1 伸臂重心計算'!$E16:I$16)-'附件1 伸臂重心計算'!I$4)} | J37: {=IF(OR('附件1 伸臂重心計算'!$D16>'附件1 伸臂重心計算'!$L$4,'附件1 伸臂重心計算'!J$6>'附件1 伸臂重心計算'!$L$7),"",SUM('附件1 伸臂重心計算'!$E4:J$4*'附件1 伸臂重心計算'!$E16:J$16)-'附件1 伸臂重心計算'!J$4)} | L37: =IF('附件1 伸臂重心計算'!D16<='附件1 伸臂重心計算'!$L$4,'附件1 伸臂重心計算'!D16&"節時前端等價質量","") -> 3節時前端等價質量
A38: 伸出3節時終點 | E38: {=IF(OR('附件1 伸臂重心計算'!$D16>'附件1 伸臂重心計算'!$L$4,'附件1 伸臂重心計算'!E$6>'附件1 伸臂重心計算'!$L$7),"",SUM('附件1 伸臂重心計算'!$E4:F$4*'附件1 伸臂重心計算'!$E16:F$16))} -> 633 | F38: {=IF(OR('附件1 伸臂重心計算'!$D16>'附件1 伸臂重心計算'!$L$4,'附件1 伸臂重心計算'!F$6>'附件1 伸臂重心計算'!$L$7),"",SUM('附件1 伸臂重心計算'!$E4:G$4*'附件1 伸臂重心計算'!$E16:G$16))} -> 872 | G38: {=IF(OR('附件1 伸臂重心計算'!$D16>'附件1 伸臂重心計算'!$L$4,'附件1 伸臂重心計算'!G$6>'附件1 伸臂重心計算'!$L$7),"",SUM('附件1 伸臂重心計算'!$E4:H$4*'附件1 伸臂重心計算'!$E16:H$16))} -> 872 | H38: {=IF(OR('附件1 伸臂重心計算'!$D16>'附件1 伸臂重心計算'!$L$4,'附件1 伸臂重心計算'!H$6>'附件1 伸臂重心計算'!$L$7),"",SUM('附件1 伸臂重心計算'!$E4:I$4*'附件1 伸臂重心計算'!$E16:I$16))} | I38: {=IF(OR('附件1 伸臂重心計算'!$D16>'附件1 伸臂重心計算'!$L$4,'附件1 伸臂重心計算'!I$6>'附件1 伸臂重心計算'!$L$7),"",SUM('附件1 伸臂重心計算'!$E4:J$4*'附件1 伸臂重心計算'!$E16:J$16))} | J38: {=IF(OR('附件1 伸臂重心計算'!$D16>'附件1 伸臂重心計算'!$L$4,'附件1 伸臂重心計算'!J$6>'附件1 伸臂重心計算'!$L$7),"",SUM('附件1 伸臂重心計算'!$E4:K$4*'附件1 伸臂重心計算'!$E16:K$16))}
A39: 超出重心之長度 | E39: =IF(E38="","",IF(E38>='附件1 伸臂重心計算'!$L17,IF(E37>'附件1 伸臂重心計算'!$L17,E38-E37,E38-'附件1 伸臂重心計算'!$L17),0)) -> 104.53654 | F39: =IF(F38="","",IF(F38>='附件1 伸臂重心計算'!$L17,IF(F37>'附件1 伸臂重心計算'!$L17,F38-F37,F38-'附件1 伸臂重心計算'!$L17),0)) -> 343.53654 | G39: =IF(G38="","",IF(G38>='附件1 伸臂重心計算'!$L17,IF(G37>'附件1 伸臂重心計算'!$L17,G38-G37,G38-'附件1 伸臂重心計算'!$L17),0)) -> 239 | H39: =IF(H38="","",IF(H38>='附件1 伸臂重心計算'!$L17,IF(H37>'附件1 伸臂重心計算'!$L17,H38-H37,H38-'附件1 伸臂重心計算'!$L17),0)) | I39: =IF(I38="","",IF(I38>='附件1 伸臂重心計算'!$L17,IF(I37>'附件1 伸臂重心計算'!$L17,I38-I37,I38-'附件1 伸臂重心計算'!$L17),0)) | J39: =IF(J38="","",IF(J38>='附件1 伸臂重心計算'!$L17,IF(J37>'附件1 伸臂重心計算'!$L17,J15-J37,J15-'附件1 伸臂重心計算'!$L17),0)) | L39: {=SUM(IF(ISERROR(E39:J39/(E38:J38-E37:J37)*'附件1 伸臂重心計算'!$E$7:$H$8),0,E39:J39/(E38:J38-E37:J37)*'附件1 伸臂重心計算'!$E$7:$H$8))} -> 63.838616
A40: 伸出4節時起點 | E40: {=IF(OR('附件1 伸臂重心計算'!$D19>'附件1 伸臂重心計算'!$L$4,'附件1 伸臂重心計算'!E$6>'附件1 伸臂重心計算'!$L$7),"",SUM('附件1 伸臂重心計算'!$E4:E$4*'附件1 伸臂重心計算'!$E19:E19)-'附件1 伸臂重心計算'!E$4)} -> 0 | F40: {=IF(OR('附件1 伸臂重心計算'!$D19>'附件1 伸臂重心計算'!$L$4,'附件1 伸臂重心計算'!F$6>'附件1 伸臂重心計算'!$L$7),"",SUM('附件1 伸臂重心計算'!$E4:F$4*'附件1 伸臂重心計算'!$E19:F19)-'附件1 伸臂重心計算'!F$4)} -> 393 | G40: {=IF(OR('附件1 伸臂重心計算'!$D19>'附件1 伸臂重心計算'!$L$4,'附件1 伸臂重心計算'!G$6>'附件1 伸臂重心計算'!$L$7),"",SUM('附件1 伸臂重心計算'!$E4:G$4*'附件1 伸臂重心計算'!$E19:G19)-'附件1 伸臂重心計算'!G$4)} -> 633 | H40: {=IF(OR('附件1 伸臂重心計算'!$D19>'附件1 伸臂重心計算'!$L$4,'附件1 伸臂重心計算'!H$6>'附件1 伸臂重心計算'!$L$7),"",SUM('附件1 伸臂重心計算'!$E4:H$4*'附件1 伸臂重心計算'!$E19:H19)-'附件1 伸臂重心計算'!H$4)} | I40: {=IF(OR('附件1 伸臂重心計算'!$D19>'附件1 伸臂重心計算'!$L$4,'附件1 伸臂重心計算'!I$6>'附件1 伸臂重心計算'!$L$7),"",SUM('附件1 伸臂重心計算'!$E4:I$4*'附件1 伸臂重心計算'!$E19:I19)-'附件1 伸臂重心計算'!I$4)} | J40: {=IF(OR('附件1 伸臂重心計算'!$D19>'附件1 伸臂重心計算'!$L$4,'附件1 伸臂重心計算'!J$6>'附件1 伸臂重心計算'!$L$7),"",SUM('附件1 伸臂重心計算'!$E4:J$4*'附件1 伸臂重心計算'!$E19:J19)-'附件1 伸臂重心計算'!J$4)} | L40: =IF('附件1 伸臂重心計算'!D19<='附件1 伸臂重心計算'!$L$4,'附件1 伸臂重心計算'!D19&"節時前端等價質量","") -> 4節時前端等價質量
...

Sheet 附件3 車台重心高度計算
B2: 1. | C2: 車台(不含起重機) | G2: 重心至地面垂直距離 | L2: (h1) | N2: = | O2: 92 | Q2: (cm)
B3: 2. | C3: 車台(不含起重機) | G3: 重量 | L3: (Ws) | N3: = | O3: =安定度計算!L8 -> 6204 | Q3: (kg)
B5: 3. | C5: 腳架、立拱重量 | G5: 重心至地面垂直距離 | L5: (h2) | N5: = | O5: 130.7 | Q5: (cm)
B6: 4. | C6: 腳架、立拱重量 | G6: 重量 | L6: (Wf) | N6: = | O6: =安定度計算!L6 -> 1187 | Q6: (kg)
B8: 5. | C8: 吊具組 | G8: 重心至地面垂直距離 | L8: (h3) | N8: = | O8: 261.7 | Q8: (cm)
B9: 6. | C9: 吊具組 | G9: 重量 | L9: (Wh) | N9: = | O9: =安定度計算!L9 -> 30 | Q9: (kg)
B11: 7. | C11: 伸臂 | G11: 重心至地面垂直距離 | L11: (h4) | N11: = | O11: 325.2 | Q11: (cm)
